Workbook
Name daysnew: [1]Eingabe!$J$3
Name Entryshavday: [1]Eingabe!$AL$6
Name Entryshavnew: [1]Eingabe!$AM$6
Name Entryshavprv: [1]Eingabe!$AK$6
Name Entryshbonday: [1]Eingabe!$AL$4
Name Entryshbonnew: [1]Eingabe!$AM$4
Name Entryshbonprv: [1]Eingabe!$AK$4
Name Entryshgmday: [1]Eingabe!$AN$3
Name Entryshgmnew: [1]Eingabe!$AN$4
Name Entryshgmprv: [1]Eingabe!$AN$2
Name Entryshnamoff: [1]Eingabe!$AJ$2
Name Entryshpinsday: [1]Eingabe!$AL$2
Name Entryshpinsnew: [1]Eingabe!$AM$2
Name Entryshpinsprv: [1]Eingabe!$AK$2
Name Entryshpointday: [1]Eingabe!$AL$3
Name Entryshpointnew: [1]Eingabe!$AM$3
Name Entryshpointprv: [1]Eingabe!$AK$3
Name Entryshsize: [1]Eingabe!$AE$1
Name Entryshtabhsz: [1]Eingabe!$AJ$5
Name Entryshtabvsz: [1]Eingabe!$AJ$4
Name Entryshtnumoffs: [1]Eingabe!$AJ$3
Name Entryshtotday: [1]Eingabe!$AL$5
Name Entryshtotprv: [1]Eingabe!$AK$5
Name Gamesfix: [1]Eingabe!$P$8
Name Gameshavoffs: [1]Eingabe!$AI$5
Name Gameshavpos: [1]Eingabe!$AE$3
Name Gameshgmpos: [1]Eingabe!$AE$4
Name Gameshpinspos: [1]Eingabe!$AE$5
Name Gameshplnum: [1]Eingabe!$AI$4
Name Gameshpnpos: [1]Eingabe!$AI$2
Name Gameshsize: [1]Eingabe!$AI$1
Name Gameshtpinpos: [1]Eingabe!$AQ$4
Name Gameshtpntpos: [1]Eingabe!$AQ$5
Name gamesnew: [1]Eingabe!$J$2
Name GamshEDVpos: [1]Eingabe!$AE$2
Name Teamshbase: [1]RL!$A$11
Name Teamshnum: [1]RL!$A$13
Name Teamshoffs: [1]RL!$A$12
Name Teamshsize: [1]RL!$A$15
Name teamsnew: [1]Eingabe!$J$1

Sheet Spielorte
A1: 1 | B1: 04.10./05.10. | C1: Regensburg Super Bowl | E1: Bamberg Bowlinghaus
A2: 2 | B2: 18.10./19.10. | C2: Unterföhring Dreambowl Palace | E2: Bayreuth Blu Bowl
A3: 3 | B3: 08.11./09.11. | C3: Brunnthal Max Munich | E3: Brunnthal Max Munich
A4: 4 | B4: 30.01./01.02. | C4: Regensburg Super Bowl | E4: Dettelbach Extreme Bowlingarena
A5: 5 | B5: 28.02./01.03. | C5: Schweinfurt Extreme Bowlingarena | E5: Friedrichshafen Seaside
A6: 6 | B6: 11.04./12.04. | C6: Unterföhring Dreambowl Palace | E6: Garmisch Zugspitzbowling
E7: Ingolstadt Cosmos Bowling Arena
E8: Kempten Big Bowl
E9: Landshut LA-Bowling
E10: Lauterach Strike-Center
E11: München Hollywood Super Bowling
E12: München Isar Bowling
E13: Nürnberg West Bowling
E14: Olching 5005 Bowling
E15: Pfaffenhofen Hollywood Super Bowling
E16: Regensburg Super Bowl
E17: Rottendorf Bowling-Center
A18: Saison: | C18: 2025/2026 | E18: Salzburg Sport-Oase
E19: Schweinfurt Extreme Bowlingarena
A20: Ligaauswertung für | E20: Unterföhring Dreambowl Palace
A21: 10 | B21: Mannschaften | E21: Würzburg Midnight Bowling
A22: 6 | B22: Spieltage
A23: 9 | B23: Spiele / Tag
A622: letzte Korrektur MS 23.01.2023

Sheet Schlüssel
C1: Bayernliga Herren | M1: =VLOOKUP($S$2,Spielorte!$A$1:$C$6,2) -> 04.10./05.10. | W1: =+C1 -> Bayernliga Herren | AG1: =VLOOKUP($AM$2,Spielorte!$A$1:$C$6,2) -> 18.10./19.10. | AQ1: =+W1 -> Bayernliga Herren | BA1: =VLOOKUP($BG$2,Spielorte!$A$1:$C$6,2) -> 08.11./09.11. | BK1: =+AQ1 -> Bayernliga Herren | BU1: =VLOOKUP($CA$2,Spielorte!$A$1:$C$6,2) -> 30.01./01.02. | CE1: =+BK1 -> Bayernliga Herren | CO1: =VLOOKUP($CU$2,Spielorte!$A$1:$C$6,2) -> 28.02./01.03. | CY1: =+CE1 -> Bayernliga Herren | DI1: =VLOOKUP($DO$2,Spielorte!$A$1:$C$6,2) -> 11.04./12.04.
C2: =VLOOKUP($S$2,Spielorte!$A$1:$C$6,3) -> Regensburg Super Bowl | M2: Spieltag | S2: 1 | W2: =VLOOKUP($AM$2,Spielorte!$A$1:$C$6,3) -> Unterföhring Dreambowl Palace | AG2: Spieltag | AM2: 2 | AQ2: =VLOOKUP($BG$2,Spielorte!$A$1:$C$6,3) -> Brunnthal Max Munich | BA2: Spieltag | BG2: 3 | BK2: =VLOOKUP($CA$2,Spielorte!$A$1:$C$6,3) -> Regensburg Super Bowl | BU2: Spieltag | CA2: 4 | CE2: =VLOOKUP($CU$2,Spielorte!$A$1:$C$6,3) -> Schweinfurt Extreme Bowlingarena | CO2: Spieltag | CU2: 5 | CY2: =VLOOKUP($DO$2,Spielorte!$A$1:$C$6,3) -> Unterföhring Dreambowl Palace | DI2: Spieltag | DO2: 6
C3: Gegner | M3: Bahn | V3: Startbahn: | W3: Gegner | AG3: Bahn | AP3: Startbahn: | AQ3: Gegner | BA3: Bahn | BJ3: Startbahn: | BK3: Gegner | BU3: Bahn | CD3: Startbahn: | CE3: Gegner | CO3: Bahn | CX3: Startbahn: | CY3: Gegner | DI3: Bahn | DR3: Startbahn:
C4: Sp 1 | D4: Sp 2 | E4: Sp 3 | F4: Sp 4 | G4: Sp 5 | H4: Sp 6 | I4: Sp 7 | J4: Sp 8 | K4: Sp 9 | M4: Sp 1 | N4: Sp 2 | O4: Sp 3 | P4: Sp 4 | Q4: Sp 5 | R4: Sp 6 | S4: Sp 7 | T4: Sp 8 | U4: Sp 9 | V4: =Erfassung1!AY4 -> 3 | W4: Sp 1 | X4: Sp 2 | Y4: Sp 3 | Z4: Sp 4 | AA4: Sp 5 | AB4: Sp 6 | AC4: Sp 7 | AD4: Sp 8 | AE4: Sp 9 | AG4: Sp 1 | AH4: Sp 2 | AI4: Sp 3 | AJ4: Sp 4 | AK4: Sp 5 | AL4: Sp 6 | AM4: Sp 7 | AN4: Sp 8 | AO4: Sp 9 | AP4: =Erfassung2!AY4 -> 12 | AQ4: Sp 1 | AR4: Sp 2 | AS4: Sp 3 | AT4: Sp 4 | AU4: Sp 5 | AV4: Sp 6 | AW4: Sp 7 | AX4: Sp 8 | AY4: Sp 9 | BA4: Sp 1 | BB4: Sp 2 | BC4: Sp 3 | BD4: Sp 4 | BE4: Sp 5 | BF4: Sp 6 | BG4: Sp 7 | BH4: Sp 8 | BI4: Sp 9 | BJ4: =Erfassung3!AY4 -> 11 | BK4: Sp 1 | BL4: Sp 2 | BM4: Sp 3 | BN4: Sp 4 | BO4: Sp 5 | BP4: Sp 6 | BQ4: Sp 7 | BR4: Sp 8 | BS4: Sp 9 | BU4: Sp 1 | BV4: Sp 2 | BW4: Sp 3 | BX4: Sp 4 | BY4: Sp 5 | BZ4: Sp 6 | CA4: Sp 7 | CB4: Sp 8 | CC4: Sp 9 | CD4: =Erfassung4!AY4 -> 11 | CE4: Sp 1 | CF4: Sp 2 | CG4: Sp 3 | CH4: Sp 4 | CI4: Sp 5 | CJ4: Sp 6 | CK4: Sp 7 | CL4: Sp 8 | CM4: Sp 9 | CO4: Sp 1 | CP4: Sp 2 | CQ4: Sp 3 | CR4: Sp 4 | CS4: Sp 5 | CT4: Sp 6 | CU4: Sp 7 | CV4: Sp 8 | CW4: Sp 9 | CX4: =Erfassung5!AY4 -> 11 | CY4: Sp 1 | CZ4: Sp 2 | DA4: Sp 3 | DB4: Sp 4 | DC4: Sp 5 | DD4: Sp 6 | DE4: Sp 7 | DF4: Sp 8 | DG4: Sp 9 | DI4: Sp 1 | DJ4: Sp 2 | DK4: Sp 3 | DL4: Sp 4 | DM4: Sp 5 | DN4: Sp 6 | DO4: Sp 7 | DP4: Sp 8 | DQ4: Sp 9 | DR4: =Erfassung6!AY4 -> 11
A5: 1 | B5: BC Comet Nürnberg | C5: 3 | D5: 9 | E5: 6 | F5: 5 | G5: 10 | H5: 7 | I5: 4 | J5: 2 | K5: 8 | L5: =SUM(C5:K5) -> 54 | M5: =M16+$V$4-1 -> 7 | N5: =N16+$V$4-1 -> 6 | O5: =O16+$V$4-1 -> 9 | P5: =P16+$V$4-1 -> 11 | Q5: =Q16+$V$4-1 -> 3 | R5: =R16+$V$4-1 -> 5 | S5: =S16+$V$4-1 -> 12 | T5: =T16+$V$4-1 -> 10 | U5: =U16+$V$4-1 -> 4 | V5: =SUM(M5:U5) -> 67 | W5: 8 | X5: 2 | Y5: 4 | Z5: 7 | AA5: 10 | AB5: 5 | AC5: 6 | AD5: 9 | AE5: 3 | AF5: =SUM(W5:AE5) -> 54 | AG5: =AG16+$AP$4-1 -> 14 | AH5: =AH16+$AP$4-1 -> 20 | AI5: =AI16+$AP$4-1 -> 16 | AJ5: =AJ16+$AP$4-1 -> 19 | AK5: =AK16+$AP$4-1 -> 15 | AL5: =AL16+$AP$4-1 -> 17 | AM5: =AM16+$AP$4-1 -> 21 | AN5: =AN16+$AP$4-1 -> 18 | AO5: =AO16+$AP$4-1 -> 13 | AP5: =SUM(AG5:AO5) -> 153 | AQ5: 5 | AR5: 3 | AS5: 8 | AT5: 2 | AU5: 6 | AV5: 4 | AW5: 7 | AX5: 9 | AY5: 10 | AZ5: =SUM(AQ5:AY5) -> 54 | BA5: =BA16+$BJ$4-1 -> 12 | BB5: =BB16+$BJ$4-1 -> 19 | BC5: =BC16+$BJ$4-1 -> 15 | BD5: =BD16+$BJ$4-1 -> 11 | BE5: =BE16+$BJ$4-1 -> 14 | BF5: =BF16+$BJ$4-1 -> 17 | BG5: =BG16+$BJ$4-1 -> 20 | BH5: =BH16+$BJ$4-1 -> 16 | BI5: =BI16+$BJ$4-1 -> 18 | BJ5: =SUM(BA5:BI5) -> 142 | BK5: 10 | BL5: 9 | BM5: 7 | BN5: 4 | BO5: 6 | BP5: 2 | BQ5: 8 | BR5: 3 | BS5: 5 | BT5: =SUM(BK5:BS5) -> 54 | BU5: =BU16+$CD$4-1 -> 19 | BV5: =BV16+$CD$4-1 -> 11 | BW5: =BW16+$CD$4-1 -> 15 | BX5: =BX16+$CD$4-1 -> 20 | BY5: =BY16+$CD$4-1 -> 17 | BZ5: =BZ16+$CD$4-1 -> 14 | CA5: =CA16+$CD$4-1 -> 12 | CB5: =CB16+$CD$4-1 -> 16 | CC5: =CC16+$CD$4-1 -> 13 | CD5: =SUM(BU5:CC5) -> 137 | CE5: 2 | CF5: 6 | CG5: 10 | CH5: 9 | CI5: 4 | CJ5: 3 | CK5: 5 | CL5: 8 | CM5: 7 | CN5: =SUM(CE5:CM5) -> 54 | CO5: =CO16+$CX$4-1 -> 19 | CP5: =CP16+$CX$4-1 -> 16 | CQ5: =CQ16+$CX$4-1 -> 18 | CR5: =CR16+$CX$4-1 -> 20 | CS5: =CS16+$CX$4-1 -> 12 | CT5: =CT16+$CX$4-1 -> 14 | CU5: =CU16+$CX$4-1 -> 17 | CV5: =CV16+$CX$4-1 -> 15 | CW5: =CW16+$CX$4-1 -> 11 | CX5: =SUM(CO5:CW5) -> 142 | CY5: 7 | CZ5: 8 | DA5: 5 | DB5: 3 | DC5: 4 | DD5: 9 | DE5: 10 | DF5: 6 | DG5: 2 | DH5: =SUM(CY5:DG5) -> 54 | DI5: =DI16+$DR$4-1 -> 14 | DJ5: =DJ16+$DR$4-1 -> 20 | DK5: =DK16+$DR$4-1 -> 16 | DL5: =DL16+$DR$4-1 -> 17 | DM5: =DM16+$DR$4-1 -> 13 | DN5: =DN16+$DR$4-1 -> 11 | DO5: =DO16+$DR$4-1 -> 15 | DP5: =DP16+$DR$4-1 -> 19 | DQ5: =DQ16+$DR$4-1 -> 12 | DR5: =SUM(DI5:DQ5) -> 137
A6: 2 | B6: BK München 3 | C6: 6 | D6: 4 | E6: 8 | F6: 7 | G6: 3 | H6: 5 | I6: 10 | J6: 1 | K6: 9 | L6: =SUM(C6:K6) -> 53 | M6: =M17+$V$4-1 -> 3 | N6: =N17+$V$4-1 -> 11 | O6: =O17+$V$4-1 -> 8 | P6: =P17+$V$4-1 -> 6 | Q6: =Q17+$V$4-1 -> 10 | R6: =R17+$V$4-1 -> 4 | S6: =S17+$V$4-1 -> 7 | T6: =T17+$V$4-1 -> 9 | U6: =U17+$V$4-1 -> 5 | V6: =SUM(M6:U6) -> 63 | W6: 9 | X6: 1 | Y6: 10 | Z6: 5 | AA6: 3 | AB6: 7 | AC6: 8 | AD6: 4 | AE6: 6 | AF6: =SUM(W6:AE6) -> 53 | AG6: =AG17+$AP$4-1 -> 19 | AH6: =AH17+$AP$4-1 -> 21 | AI6: =AI17+$AP$4-1 -> 13 | AJ6: =AJ17+$AP$4-1 -> 14 | AK6: =AK17+$AP$4-1 -> 20 | AL6: =AL17+$AP$4-1 -> 18 | AM6: =AM17+$AP$4-1 -> 12 | AN6: =AN17+$AP$4-1 -> 17 | AO6: =AO17+$AP$4-1 -> 15 | AP6: =SUM(AG6:AO6) -> 149 | AQ6: 8 | AR6: 10 | AS6: 3 | AT6: 1 | AU6: 7 | AV6: 6 | AW6: 9 | AX6: 5 | AY6: 4 | AZ6: =SUM(AQ6:AY6) -> 53 | BA6: =BA17+$BJ$4-1 -> 20 | BB6: =BB17+$BJ$4-1 -> 15 | BC6: =BC17+$BJ$4-1 -> 14 | BD6: =BD17+$BJ$4-1 -> 12 | BE6: =BE17+$BJ$4-1 -> 16 | BF6: =BF17+$BJ$4-1 -> 19 | BG6: =BG17+$BJ$4-1 -> 11 | BH6: =BH17+$BJ$4-1 -> 17 | BI6: =BI17+$BJ$4-1 -> 13 | BJ6: =SUM(BA6:BI6) -> 137 | BK6: 4 | BL6: 5 | BM6: 9 | BN6: 6 | BO6: 7 | BP6: 1 | BQ6: 3 | BR6: 10 | BS6: 8 | BT6: =SUM(BK6:BS6) -> 53 | BU6: =BU17+$CD$4-1 -> 18 | BV6: =BV17+$CD$4-1 -> 20 | BW6: =BW17+$CD$4-1 -> 14 | BX6: =BX17+$CD$4-1 -> 16 | BY6: =BY17+$CD$4-1 -> 11 | BZ6: =BZ17+$CD$4-1 -> 13 | CA6: =CA17+$CD$4-1 -> 17 | CB6: =CB17+$CD$4-1 -> 12 | CC6: =CC17+$CD$4-1 -> 15 | CD6: =SUM(BU6:CC6) -> 136 | CE6: 1 | CF6: 9 | CG6: 3 | CH6: 10 | CI6: 6 | CJ6: 7 | CK6: 8 | CL6: 4 | CM6: 5 | CN6: =SUM(CE6:CM6) -> 53 | CO6: =CO17+$CX$4-1 -> 20 | CP6: =CP17+$CX$4-1 -> 17 | CQ6: =CQ17+$CX$4-1 -> 12 | CR6: =CR17+$CX$4-1 -> 13 | CS6: =CS17+$CX$4-1 -> 15 | CT6: =CT17+$CX$4-1 -> 18 | CU6: =CU17+$CX$4-1 -> 14 | CV6: =CV17+$CX$4-1 -> 11 | CW6: =CW17+$CX$4-1 -> 16 | CX6: =SUM(CO6:CW6) -> 136 | CY6: 5 | CZ6: 4 | DA6: 8 | DB6: 7 | DC6: 6 | DD6: 10 | DE6: 3 | DF6: 9 | DG6: 1 | DH6: =SUM(CY6:DG6) -> 53 | DI6: =DI17+$DR$4-1 -> 19 | DJ6: =DJ17+$DR$4-1 -> 14 | DK6: =DK17+$DR$4-1 -> 17 | DL6: =DL17+$DR$4-1 -> 15 | DM6: =DM17+$DR$4-1 -> 20 | DN6: =DN17+$DR$4-1 -> 18 | DO6: =DO17+$DR$4-1 -> 13 | DP6: =DP17+$DR$4-1 -> 16 | DQ6: =DQ17+$DR$4-1 -> 11 | DR6: =SUM(DI6:DQ6) -> 143
A7: 3 | B7: SG DJK Rimpar 1 | C7: 1 | D7: 10 | E7: 5 | F7: 9 | G7: 2 | H7: 6 | I7: 8 | J7: 4 | K7: 7 | L7: =SUM(C7:K7) -> 52 | M7: =M18+$V$4-1 -> 8 | N7: =N18+$V$4-1 -> 4 | O7: =O18+$V$4-1 -> 6 | P7: =P18+$V$4-1 -> 7 | Q7: =Q18+$V$4-1 -> 9 | R7: =R18+$V$4-1 -> 12 | S7: =S18+$V$4-1 -> 5 | T7: =T18+$V$4-1 -> 3 | U7: =U18+$V$4-1 -> 10 | V7: =SUM(M7:U7) -> 64 | W7: 7 | X7: 4 | Y7: 8 | Z7: 6 | AA7: 2 | AB7: 9 | AC7: 5 | AD7: 10 | AE7: 1 | AF7: =SUM(W7:AE7) -> 52 | AG7: =AG18+$AP$4-1 -> 20 | AH7: =AH18+$AP$4-1 -> 15 | AI7: =AI18+$AP$4-1 -> 19 | AJ7: =AJ18+$AP$4-1 -> 16 | AK7: =AK18+$AP$4-1 -> 21 | AL7: =AL18+$AP$4-1 -> 13 | AM7: =AM18+$AP$4-1 -> 18 | AN7: =AN18+$AP$4-1 -> 14 | AO7: =AO18+$AP$4-1 -> 12 | AP7: =SUM(AG7:AO7) -> 148 | AQ7: 10 | AR7: 1 | AS7: 2 | AT7: 6 | AU7: 9 | AV7: 7 | AW7: 5 | AX7: 4 | AY7: 8 | AZ7: =SUM(AQ7:AY7) -> 52 | BA7: =BA18+$BJ$4-1 -> 17 | BB7: =BB18+$BJ$4-1 -> 20 | BC7: =BC18+$BJ$4-1 -> 13 | BD7: =BD18+$BJ$4-1 -> 16 | BE7: =BE18+$BJ$4-1 -> 18 | BF7: =BF18+$BJ$4-1 -> 11 | BG7: =BG18+$BJ$4-1 -> 14 | BH7: =BH18+$BJ$4-1 -> 19 | BI7: =BI18+$BJ$4-1 -> 12 | BJ7: =SUM(BA7:BI7) -> 140 | BK7: 8 | BL7: 4 | BM7: 5 | BN7: 7 | BO7: 9 | BP7: 6 | BQ7: 2 | BR7: 1 | BS7: 10 | BT7: =SUM(BK7:BS7) -> 52 | BU7: =BU18+$CD$4-1 -> 13 | BV7: =BV18+$CD$4-1 -> 16 | BW7: =BW18+$CD$4-1 -> 17 | BX7: =BX18+$CD$4-1 -> 14 | BY7: =BY18+$CD$4-1 -> 19 | BZ7: =BZ18+$CD$4-1 -> 11 | CA7: =CA18+$CD$4-1 -> 18 | CB7: =CB18+$CD$4-1 -> 15 | CC7: =CC18+$CD$4-1 -> 20 | CD7: =SUM(BU7:CC7) -> 143 | CE7: 4 | CF7: 7 | CG7: 2 | CH7: 5 | CI7: 8 | CJ7: 1 | CK7: 10 | CL7: 9 | CM7: 6 | CN7: =SUM(CE7:CM7) -> 52 | CO7: =CO18+$CX$4-1 -> 16 | CP7: =CP18+$CX$4-1 -> 20 | CQ7: =CQ18+$CX$4-1 -> 11 | CR7: =CR18+$CX$4-1 -> 15 | CS7: =CS18+$CX$4-1 -> 17 | CT7: =CT18+$CX$4-1 -> 13 | CU7: =CU18+$CX$4-1 -> 12 | CV7: =CV18+$CX$4-1 -> 19 | CW7: =CW18+$CX$4-1 -> 14 | CX7: =SUM(CO7:CW7) -> 137 | CY7: 6 | CZ7: 9 | DA7: 10 | DB7: 1 | DC7: 8 | DD7: 5 | DE7: 2 | DF7: 7 | DG7: 4 | DH7: =SUM(CY7:DG7) -> 52 | DI7: =DI18+$DR$4-1 -> 17 | DJ7: =DJ18+$DR$4-1 -> 12 | DK7: =DK18+$DR$4-1 -> 13 | DL7: =DL18+$DR$4-1 -> 18 | DM7: =DM18+$DR$4-1 -> 16 | DN7: =DN18+$DR$4-1 -> 20 | DO7: =DO18+$DR$4-1 -> 14 | DP7: =DP18+$DR$4-1 -> 11 | DQ7: =DQ18+$DR$4-1 -> 19 | DR7: =SUM(DI7:DQ7) -> 140
A8: 4 | B8: SG Rottendorf 1 | C8: 7 | D8: 2 | E8: 9 | F8: 10 | G8: 6 | H8: 8 | I8: 1 | J8: 3 | K8: 5 | L8: =SUM(C8:K8) -> 51 | M8: =M19+$V$4-1 -> 9 | N8: =N19+$V$4-1 -> 12 | O8: =O19+$V$4-1 -> 3 | P8: =P19+$V$4-1 -> 10 | Q8: =Q19+$V$4-1 -> 5 | R8: =R19+$V$4-1 -> 7 | S8: =S19+$V$4-1 -> 11 | T8: =T19+$V$4-1 -> 4 | U8: =U19+$V$4-1 -> 8 | V8: =SUM(M8:U8) -> 69 | W8: 5 | X8: 3 | Y8: 1 | Z8: 8 | AA8: 6 | AB8: 10 | AC8: 9 | AD8: 2 | AE8: 7 | AF8: =SUM(W8:AE8) -> 51 | AG8: =AG19+$AP$4-1 -> 12 | AH8: =AH19+$AP$4-1 -> 14 | AI8: =AI19+$AP$4-1 -> 17 | AJ8: =AJ19+$AP$4-1 -> 13 | AK8: =AK19+$AP$4-1 -> 19 | AL8: =AL19+$AP$4-1 -> 20 | AM8: =AM19+$AP$4-1 -> 15 | AN8: =AN19+$AP$4-1 -> 16 | AO8: =AO19+$AP$4-1 -> 21 | AP8: =SUM(AG8:AO8) -> 147 | AQ8: 6 | AR8: 5 | AS8: 9 | AT8: 7 | AU8: 8 | AV8: 1 | AW8: 10 | AX8: 3 | AY8: 2 | AZ8: =SUM(AQ8:AY8) -> 51 | BA8: =BA19+$BJ$4-1 -> 15 | BB8: =BB19+$BJ$4-1 -> 13 | BC8: =BC19+$BJ$4-1 -> 12 | BD8: =BD19+$BJ$4-1 -> 17 | BE8: =BE19+$BJ$4-1 -> 19 | BF8: =BF19+$BJ$4-1 -> 18 | BG8: =BG19+$BJ$4-1 -> 16 | BH8: =BH19+$BJ$4-1 -> 20 | BI8: =BI19+$BJ$4-1 -> 14 | BJ8: =SUM(BA8:BI8) -> 144 | BK8: 2 | BL8: 3 | BM8: 10 | BN8: 1 | BO8: 8 | BP8: 7 | BQ8: 9 | BR8: 5 | BS8: 6 | BT8: =SUM(BK8:BS8) -> 51 | BU8: =BU19+$CD$4-1 -> 17 | BV8: =BV19+$CD$4-1 -> 15 | BW8: =BW19+$CD$4-1 -> 11 | BX8: =BX19+$CD$4-1 -> 19 | BY8: =BY19+$CD$4-1 -> 16 | BZ8: =BZ19+$CD$4-1 -> 20 | CA8: =CA19+$CD$4-1 -> 13 | CB8: =CB19+$CD$4-1 -> 18 | CC8: =CC19+$CD$4-1 -> 12 | CD8: =SUM(BU8:CC8) -> 141 | CE8: 3 | CF8: 8 | CG8: 5 | CH8: 7 | CI8: 1 | CJ8: 10 | CK8: 6 | CL8: 2 | CM8: 9 | CN8: =SUM(CE8:CM8) -> 51 | CO8: =CO19+$CX$4-1 -> 15 | CP8: =CP19+$CX$4-1 -> 13 | CQ8: =CQ19+$CX$4-1 -> 19 | CR8: =CR19+$CX$4-1 -> 17 | CS8: =CS19+$CX$4-1 -> 11 | CT8: =CT19+$CX$4-1 -> 16 | CU8: =CU19+$CX$4-1 -> 20 | CV8: =CV19+$CX$4-1 -> 12 | CW8: =CW19+$CX$4-1 -> 18 | CX8: =SUM(CO8:CW8) -> 141 | CY8: 9 | CZ8: 2 | DA8: 6 | DB8: 10 | DC8: 1 | DD8: 7 | DE8: 5 | DF8: 8 | DG8: 3 | DH8: =SUM(CY8:DG8) -> 51 | DI8: =DI19+$DR$4-1 -> 15 | DJ8: =DJ19+$DR$4-1 -> 13 | DK8: =DK19+$DR$4-1 -> 11 | DL8: =DL19+$DR$4-1 -> 19 | DM8: =DM19+$DR$4-1 -> 14 | DN8: =DN19+$DR$4-1 -> 16 | DO8: =DO19+$DR$4-1 -> 12 | DP8: =DP19+$DR$4-1 -> 18 | DQ8: =DQ19+$DR$4-1 -> 20 | DR8: =SUM(DI8:DQ8) -> 138
A9: 5 | B9: BC EMAX Unterföhring 2 | C9: 9 | D9: 8 | E9: 3 | F9: 1 | G9: 7 | H9: 2 | I9: 6 | J9: 10 | K9: 4 | L9: =SUM(C9:K9) -> 50 | M9: =M20+$V$4-1 -> 11 | N9: =N20+$V$4-1 -> 9 | O9: =O20+$V$4-1 -> 5 | P9: =P20+$V$4-1 -> 12 | Q9: =Q20+$V$4-1 -> 8 | R9: =R20+$V$4-1 -> 3 | S9: =S20+$V$4-1 -> 10 | T9: =T20+$V$4-1 -> 6 | U9: =U20+$V$4-1 -> 7 | V9: =SUM(M9:U9) -> 71 | W9: 4 | X9: 10 | Y9: 6 | Z9: 2 | AA9: 7 | AB9: 1 | AC9: 3 | AD9: 8 | AE9: 9 | AF9: =SUM(W9:AE9) -> 50 | AG9: =AG20+$AP$4-1 -> 13 | AH9: =AH20+$AP$4-1 -> 18 | AI9: =AI20+$AP$4-1 -> 20 | AJ9: =AJ20+$AP$4-1 -> 15 | AK9: =AK20+$AP$4-1 -> 12 | AL9: =AL20+$AP$4-1 -> 16 | AM9: =AM20+$AP$4-1 -> 19 | AN9: =AN20+$AP$4-1 -> 21 | AO9: =AO20+$AP$4-1 -> 17 | AP9: =SUM(AG9:AO9) -> 151 | AQ9: 1 | AR9: 4 | AS9: 6 | AT9: 9 | AU9: 10 | AV9: 8 | AW9: 3 | AX9: 2 | AY9: 7 | AZ9: =SUM(AQ9:AY9) -> 50 | BA9: =BA20+$BJ$4-1 -> 11 | BB9: =BB20+$BJ$4-1 -> 14 | BC9: =BC20+$BJ$4-1 -> 17 | BD9: =BD20+$BJ$4-1 -> 20 | BE9: =BE20+$BJ$4-1 -> 12 | BF9: =BF20+$BJ$4-1 -> 16 | BG9: =BG20+$BJ$4-1 -> 13 | BH9: =BH20+$BJ$4-1 -> 18 | BI9: =BI20+$BJ$4-1 -> 15 | BJ9: =SUM(BA9:BI9) -> 136 | BK9: 7 | BL9: 2 | BM9: 3 | BN9: 8 | BO9: 10 | BP9: 9 | BQ9: 6 | BR9: 4 | BS9: 1 | BT9: =SUM(BK9:BS9) -> 50 | BU9: =BU20+$CD$4-1 -> 12 | BV9: =BV20+$CD$4-1 -> 19 | BW9: =BW20+$CD$4-1 -> 18 | BX9: =BX20+$CD$4-1 -> 11 | BY9: =BY20+$CD$4-1 -> 13 | BZ9: =BZ20+$CD$4-1 -> 15 | CA9: =CA20+$CD$4-1 -> 20 | CB9: =CB20+$CD$4-1 -> 17 | CC9: =CC20+$CD$4-1 -> 14 | CD9: =SUM(BU9:CC9) -> 139 | CE9: 6 | CF9: 10 | CG9: 4 | CH9: 3 | CI9: 9 | CJ9: 8 | CK9: 1 | CL9: 7 | CM9: 2 | CN9: =SUM(CE9:CM9) -> 50 | CO9: =CO20+$CX$4-1 -> 17 | CP9: =CP20+$CX$4-1 -> 11 | CQ9: =CQ20+$CX$4-1 -> 20 | CR9: =CR20+$CX$4-1 -> 16 | CS9: =CS20+$CX$4-1 -> 14 | CT9: =CT20+$CX$4-1 -> 19 | CU9: =CU20+$CX$4-1 -> 18 | CV9: =CV20+$CX$4-1 -> 13 | CW9: =CW20+$CX$4-1 -> 15 | CX9: =SUM(CO9:CW9) -> 143 | CY9: 2 | CZ9: 7 | DA9: 1 | DB9: 8 | DC9: 9 | DD9: 3 | DE9: 4 | DF9: 10 | DG9: 6 | DH9: =SUM(CY9:DG9) -> 50 | DI9: =DI20+$DR$4-1 -> 20 | DJ9: =DJ20+$DR$4-1 -> 18 | DK9: =DK20+$DR$4-1 -> 15 | DL9: =DL20+$DR$4-1 -> 12 | DM9: =DM20+$DR$4-1 -> 17 | DN9: =DN20+$DR$4-1 -> 19 | DO9: =DO20+$DR$4-1 -> 11 | DP9: =DP20+$DR$4-1 -> 14 | DQ9: =DQ20+$DR$4-1 -> 16 | DR9: =SUM(DI9:DQ9) -> 142
A10: 6 | B10: Bajuwaren München 1 | C10: 2 | D10: 7 | E10: 1 | F10: 8 | G10: 4 | H10: 3 | I10: 5 | J10: 9 | K10: 10 | L10: =SUM(C10:K10) -> 49 | M10: =M21+$V$4-1 -> 4 | N10: =N21+$V$4-1 -> 7 | O10: =O21+$V$4-1 -> 10 | P10: =P21+$V$4-1 -> 3 | Q10: =Q21+$V$4-1 -> 6 | R10: =R21+$V$4-1 -> 11 | S10: =S21+$V$4-1 -> 9 | T10: =T21+$V$4-1 -> 8 | U10: =U21+$V$4-1 -> 12 | V10: =SUM(M10:U10) -> 70 | W10: 10 | X10: 9 | Y10: 5 | Z10: 3 | AA10: 4 | AB10: 8 | AC10: 1 | AD10: 7 | AE10: 2 | AF10: =SUM(W10:AE10) -> 49 | AG10: =AG21+$AP$4-1 -> 16 | AH10: =AH21+$AP$4-1 -> 12 | AI10: =AI21+$AP$4-1 -> 21 | AJ10: =AJ21+$AP$4-1 -> 17 | AK10: =AK21+$AP$4-1 -> 18 | AL10: =AL21+$AP$4-1 -> 15 | AM10: =AM21+$AP$4-1 -> 20 | AN10: =AN21+$AP$4-1 -> 13 | AO10: =AO21+$AP$4-1 -> 14 | AP10: =SUM(AG10:AO10) -> 146 | AQ10: 4 | AR10: 7 | AS10: 5 | AT10: 3 | AU10: 1 | AV10: 2 | AW10: 8 | AX10: 10 | AY10: 9 | AZ10: =SUM(AQ10:AY10) -> 49 | BA10: =BA21+$BJ$4-1 -> 16 | BB10: =BB21+$BJ$4-1 -> 12 | BC10: =BC21+$BJ$4-1 -> 18 | BD10: =BD21+$BJ$4-1 -> 15 | BE10: =BE21+$BJ$4-1 -> 13 | BF10: =BF21+$BJ$4-1 -> 20 | BG10: =BG21+$BJ$4-1 -> 17 | BH10: =BH21+$BJ$4-1 -> 11 | BI10: =BI21+$BJ$4-1 -> 19 | BJ10: =SUM(BA10:BI10) -> 141 | BK10: 9 | BL10: 10 | BM10: 8 | BN10: 2 | BO10: 1 | BP10: 3 | BQ10: 5 | BR10: 7 | BS10: 4 | BT10: =SUM(BK10:BS10) -> 49 | BU10: =BU21+$CD$4-1 -> 16 | BV10: =BV21+$CD$4-1 -> 14 | BW10: =BW21+$CD$4-1 -> 20 | BX10: =BX21+$CD$4-1 -> 15 | BY10: =BY21+$CD$4-1 -> 18 | BZ10: =BZ21+$CD$4-1 -> 12 | CA10: =CA21+$CD$4-1 -> 19 | CB10: =CB21+$CD$4-1 -> 13 | CC10: =CC21+$CD$4-1 -> 11 | CD10: =SUM(BU10:CC10) -> 138 | CE10: 5 | CF10: 1 | CG10: 7 | CH10: 8 | CI10: 2 | CJ10: 9 | CK10: 4 | CL10: 10 | CM10: 3 | CN10: =SUM(CE10:CM10) -> 49 | CO10: =CO21+$CX$4-1 -> 18 | CP10: =CP21+$CX$4-1 -> 15 | CQ10: =CQ21+$CX$4-1 -> 14 | CR10: =CR21+$CX$4-1 -> 12 | CS10: =CS21+$CX$4-1 -> 16 | CT10: =CT21+$CX$4-1 -> 11 | CU10: =CU21+$CX$4-1 -> 19 | CV10: =CV21+$CX$4-1 -> 17 | CW10: =CW21+$CX$4-1 -> 13 | CX10: =SUM(CO10:CW10) -> 135 | CY10: 3 | CZ10: 10 | DA10: 4 | DB10: 9 | DC10: 2 | DD10: 8 | DE10: 7 | DF10: 1 | DG10: 5 | DH10: =SUM(CY10:DG10) -> 49 | DI10: =DI21+$DR$4-1 -> 18 | DJ10: =DJ21+$DR$4-1 -> 16 | DK10: =DK21+$DR$4-1 -> 12 | DL10: =DL21+$DR$4-1 -> 14 | DM10: =DM21+$DR$4-1 -> 19 | DN10: =DN21+$DR$4-1 -> 13 | DO10: =DO21+$DR$4-1 -> 17 | DP10: =DP21+$DR$4-1 -> 20 | DQ10: =DQ21+$DR$4-1 -> 15 | DR10: =SUM(DI10:DQ10) -> 144
A11: 7 | B11: Bowlinghaus Bamberg 1 | C11: 4 | D11: 6 | E11: 10 | F11: 2 | G11: 5 | H11: 1 | I11: 9 | J11: 8 | K11: 3 | L11: =SUM(C11:K11) -> 48 | M11: =M22+$V$4-1 -> 10 | N11: =N22+$V$4-1 -> 8 | O11: =O22+$V$4-1 -> 11 | P11: =P22+$V$4-1 -> 5 | Q11: =Q22+$V$4-1 -> 7 | R11: =R22+$V$4-1 -> 6 | S11: =S22+$V$4-1 -> 4 | T11: =T22+$V$4-1 -> 12 | U11: =U22+$V$4-1 -> 9 | V11: =SUM(M11:U11) -> 72 | W11: 3 | X11: 8 | Y11: 9 | Z11: 1 | AA11: 5 | AB11: 2 | AC11: 10 | AD11: 6 | AE11: 4 | AF11: =SUM(W11:AE11) -> 48 | AG11: =AG22+$AP$4-1 -> 21 | AH11: =AH22+$AP$4-1 -> 16 | AI11: =AI22+$AP$4-1 -> 14 | AJ11: =AJ22+$AP$4-1 -> 18 | AK11: =AK22+$AP$4-1 -> 13 | AL11: =AL22+$AP$4-1 -> 19 | AM11: =AM22+$AP$4-1 -> 17 | AN11: =AN22+$AP$4-1 -> 12 | AO11: =AO22+$AP$4-1 -> 20 | AP11: =SUM(AG11:AO11) -> 150 | AQ11: 9 | AR11: 6 | AS11: 10 | AT11: 4 | AU11: 2 | AV11: 3 | AW11: 1 | AX11: 8 | AY11: 5 | AZ11: =SUM(AQ11:AY11) -> 48 | BA11: =BA22+$BJ$4-1 -> 13 | BB11: =BB22+$BJ$4-1 -> 11 | BC11: =BC22+$BJ$4-1 -> 20 | BD11: =BD22+$BJ$4-1 -> 18 | BE11: =BE22+$BJ$4-1 -> 15 | BF11: =BF22+$BJ$4-1 -> 12 | BG11: =BG22+$BJ$4-1 -> 19 | BH11: =BH22+$BJ$4-1 -> 14 | BI11: =BI22+$BJ$4-1 -> 16 | BJ11: =SUM(BA11:BI11) -> 138 | BK11: 5 | BL11: 8 | BM11: 1 | BN11: 3 | BO11: 2 | BP11: 4 | BQ11: 10 | BR11: 6 | BS11: 9 | BT11: =SUM(BK11:BS11) -> 48 | BU11: =BU22+$CD$4-1 -> 11 | BV11: =BV22+$CD$4-1 -> 17 | BW11: =BW22+$CD$4-1 -> 16 | BX11: =BX22+$CD$4-1 -> 13 | BY11: =BY22+$CD$4-1 -> 12 | BZ11: =BZ22+$CD$4-1 -> 19 | CA11: =CA22+$CD$4-1 -> 15 | CB11: =CB22+$CD$4-1 -> 14 | CC11: =CC22+$CD$4-1 -> 18 | CD11: =SUM(BU11:CC11) -> 135 | CE11: 8 | CF11: 3 | CG11: 6 | CH11: 4 | CI11: 10 | CJ11: 2 | CK11: 9 | CL11: 5 | CM11: 1 | CN11: =SUM(CE11:CM11) -> 48 | CO11: =CO22+$CX$4-1 -> 11 | CP11: =CP22+$CX$4-1 -> 19 | CQ11: =CQ22+$CX$4-1 -> 13 | CR11: =CR22+$CX$4-1 -> 18 | CS11: =CS22+$CX$4-1 -> 20 | CT11: =CT22+$CX$4-1 -> 17 | CU11: =CU22+$CX$4-1 -> 16 | CV11: =CV22+$CX$4-1 -> 14 | CW11: =CW22+$CX$4-1 -> 12 | CX11: =SUM(CO11:CW11) -> 140 | CY11: 1 | CZ11: 5 | DA11: 9 | DB11: 2 | DC11: 10 | DD11: 4 | DE11: 6 | DF11: 3 | DG11: 8 | DH11: =SUM(CY11:DG11) -> 48 | DI11: =DI22+$DR$4-1 -> 13 | DJ11: =DJ22+$DR$4-1 -> 17 | DK11: =DK22+$DR$4-1 -> 19 | DL11: =DL22+$DR$4-1 -> 16 | DM11: =DM22+$DR$4-1 -> 11 | DN11: =DN22+$DR$4-1 -> 15 | DO11: =DO22+$DR$4-1 -> 18 | DP11: =DP22+$DR$4-1 -> 12 | DQ11: =DQ22+$DR$4-1 -> 14 | DR11: =SUM(DI11:DQ11) -> 135
A12: 8 | B12: Schanzer Ingolstadt 1 | C12: 10 | D12: 5 | E12: 2 | F12: 6 | G12: 9 | H12: 4 | I12: 3 | J12: 7 | K12: 1 | L12: =SUM(C12:K12) -> 47 | M12: =M23+$V$4-1 -> 5 | N12: =N23+$V$4-1 -> 10 | O12: =O23+$V$4-1 -> 7 | P12: =P23+$V$4-1 -> 4 | Q12: =Q23+$V$4-1 -> 12 | R12: =R23+$V$4-1 -> 8 | S12: =S23+$V$4-1 -> 6 | T12: =T23+$V$4-1 -> 11 | U12: =U23+$V$4-1 -> 3 | V12: =SUM(M12:U12) -> 66 | W12: 1 | X12: 7 | Y12: 3 | Z12: 4 | AA12: 9 | AB12: 6 | AC12: 2 | AD12: 5 | AE12: 10 | AF12: =SUM(W12:AE12) -> 47 | AG12: =AG23+$AP$4-1 -> 15 | AH12: =AH23+$AP$4-1 -> 17 | AI12: =AI23+$AP$4-1 -> 18 | AJ12: =AJ23+$AP$4-1 -> 12 | AK12: =AK23+$AP$4-1 -> 16 | AL12: =AL23+$AP$4-1 -> 14 | AM12: =AM23+$AP$4-1 -> 13 | AN12: =AN23+$AP$4-1 -> 20 | AO12: =AO23+$AP$4-1 -> 19 | AP12: =SUM(AG12:AO12) -> 144 | AQ12: 2 | AR12: 9 | AS12: 1 | AT12: 10 | AU12: 4 | AV12: 5 | AW12: 6 | AX12: 7 | AY12: 3 | AZ12: =SUM(AQ12:AY12) -> 47 | BA12: =BA23+$BJ$4-1 -> 19 | BB12: =BB23+$BJ$4-1 -> 17 | BC12: =BC23+$BJ$4-1 -> 16 | BD12: =BD23+$BJ$4-1 -> 14 | BE12: =BE23+$BJ$4-1 -> 20 | BF12: =BF23+$BJ$4-1 -> 15 | BG12: =BG23+$BJ$4-1 -> 18 | BH12: =BH23+$BJ$4-1 -> 13 | BI12: =BI23+$BJ$4-1 -> 11 | BJ12: =SUM(BA12:BI12) -> 143 | BK12: 3 | BL12: 7 | BM12: 6 | BN12: 5 | BO12: 4 | BP12: 10 | BQ12: 1 | BR12: 9 | BS12: 2 | BT12: =SUM(BK12:BS12) -> 47 | BU12: =BU23+$CD$4-1 -> 14 | BV12: =BV23+$CD$4-1 -> 18 | BW12: =BW23+$CD$4-1 -> 19 | BX12: =BX23+$CD$4-1 -> 12 | BY12: =BY23+$CD$4-1 -> 15 | BZ12: =BZ23+$CD$4-1 -> 17 | CA12: =CA23+$CD$4-1 -> 11 | CB12: =CB23+$CD$4-1 -> 20 | CC12: =CC23+$CD$4-1 -> 16 | CD12: =SUM(BU12:CC12) -> 142 | CE12: 7 | CF12: 4 | CG12: 9 | CH12: 6 | CI12: 3 | CJ12: 5 | CK12: 2 | CL12: 1 | CM12: 10 | CN12: =SUM(CE12:CM12) -> 47 | CO12: =CO23+$CX$4-1 -> 12 | CP12: =CP23+$CX$4-1 -> 14 | CQ12: =CQ23+$CX$4-1 -> 15 | CR12: =CR23+$CX$4-1 -> 11 | CS12: =CS23+$CX$4-1 -> 18 | CT12: =CT23+$CX$4-1 -> 20 | CU12: =CU23+$CX$4-1 -> 13 | CV12: =CV23+$CX$4-1 -> 16 | CW12: =CW23+$CX$4-1 -> 19 | CX12: =SUM(CO12:CW12) -> 138 | CY12: 10 | CZ12: 1 | DA12: 2 | DB12: 5 | DC12: 3 | DD12: 6 | DE12: 9 | DF12: 4 | DG12: 7 | DH12: =SUM(CY12:DG12) -> 47 | DI12: =DI23+$DR$4-1 -> 12 | DJ12: =DJ23+$DR$4-1 -> 19 | DK12: =DK23+$DR$4-1 -> 18 | DL12: =DL23+$DR$4-1 -> 11 | DM12: =DM23+$DR$4-1 -> 15 | DN12: =DN23+$DR$4-1 -> 14 | DO12: =DO23+$DR$4-1 -> 20 | DP12: =DP23+$DR$4-1 -> 17 | DQ12: =DQ23+$DR$4-1 -> 13 | DR12: =SUM(DI12:DQ12) -> 139
A13: 9 | B13: Werdenfels 1 | C13: 5 | D13: 1 | E13: 4 | F13: 3 | G13: 8 | H13: 10 | I13: 7 | J13: 6 | K13: 2 | L13: =SUM(C13:K13) -> 46 | M13: =M24+$V$4-1 -> 12 | N13: =N24+$V$4-1 -> 5 | O13: =O24+$V$4-1 -> 4 | P13: =P24+$V$4-1 -> 8 | Q13: =Q24+$V$4-1 -> 11 | R13: =R24+$V$4-1 -> 9 | S13: =S24+$V$4-1 -> 3 | T13: =T24+$V$4-1 -> 7 | U13: =U24+$V$4-1 -> 6 | V13: =SUM(M13:U13) -> 65 | W13: 2 | X13: 6 | Y13: 7 | Z13: 10 | AA13: 8 | AB13: 3 | AC13: 4 | AD13: 1 | AE13: 5 | AF13: =SUM(W13:AE13) -> 46 | AG13: =AG24+$AP$4-1 -> 18 | AH13: =AH24+$AP$4-1 -> 13 | AI13: =AI24+$AP$4-1 -> 15 | AJ13: =AJ24+$AP$4-1 -> 21 | AK13: =AK24+$AP$4-1 -> 17 | AL13: =AL24+$AP$4-1 -> 12 | AM13: =AM24+$AP$4-1 -> 14 | AN13: =AN24+$AP$4-1 -> 19 | AO13: =AO24+$AP$4-1 -> 16 | AP13: =SUM(AG13:AO13) -> 145 | AQ13: 7 | AR13: 8 | AS13: 4 | AT13: 5 | AU13: 3 | AV13: 10 | AW13: 2 | AX13: 1 | AY13: 6 | AZ13: =SUM(AQ13:AY13) -> 46 | BA13: =BA24+$BJ$4-1 -> 14 | BB13: =BB24+$BJ$4-1 -> 18 | BC13: =BC24+$BJ$4-1 -> 11 | BD13: =BD24+$BJ$4-1 -> 19 | BE13: =BE24+$BJ$4-1 -> 17 | BF13: =BF24+$BJ$4-1 -> 13 | BG13: =BG24+$BJ$4-1 -> 12 | BH13: =BH24+$BJ$4-1 -> 15 | BI13: =BI24+$BJ$4-1 -> 20 | BJ13: =SUM(BA13:BI13) -> 139 | BK13: 6 | BL13: 1 | BM13: 2 | BN13: 10 | BO13: 3 | BP13: 5 | BQ13: 4 | BR13: 8 | BS13: 7 | BT13: =SUM(BK13:BS13) -> 46 | BU13: =BU24+$CD$4-1 -> 15 | BV13: =BV24+$CD$4-1 -> 12 | BW13: =BW24+$CD$4-1 -> 13 | BX13: =BX24+$CD$4-1 -> 18 | BY13: =BY24+$CD$4-1 -> 20 | BZ13: =BZ24+$CD$4-1 -> 16 | CA13: =CA24+$CD$4-1 -> 14 | CB13: =CB24+$CD$4-1 -> 19 | CC13: =CC24+$CD$4-1 -> 17 | CD13: =SUM(BU13:CC13) -> 144 | CE13: 10 | CF13: 2 | CG13: 8 | CH13: 1 | CI13: 5 | CJ13: 6 | CK13: 7 | CL13: 3 | CM13: 4 | CN13: =SUM(CE13:CM13) -> 46 | CO13: =CO24+$CX$4-1 -> 14 | CP13: =CP24+$CX$4-1 -> 18 | CQ13: =CQ24+$CX$4-1 -> 16 | CR13: =CR24+$CX$4-1 -> 19 | CS13: =CS24+$CX$4-1 -> 13 | CT13: =CT24+$CX$4-1 -> 12 | CU13: =CU24+$CX$4-1 -> 15 | CV13: =CV24+$CX$4-1 -> 20 | CW13: =CW24+$CX$4-1 -> 17 | CX13: =SUM(CO13:CW13) -> 144 | CY13: 4 | CZ13: 3 | DA13: 7 | DB13: 6 | DC13: 5 | DD13: 1 | DE13: 8 | DF13: 2 | DG13: 10 | DH13: =SUM(CY13:DG13) -> 46 | DI13: =DI24+$DR$4-1 -> 16 | DJ13: =DJ24+$DR$4-1 -> 11 | DK13: =DK24+$DR$4-1 -> 20 | DL13: =DL24+$DR$4-1 -> 13 | DM13: =DM24+$DR$4-1 -> 18 | DN13: =DN24+$DR$4-1 -> 12 | DO13: =DO24+$DR$4-1 -> 19 | DP13: =DP24+$DR$4-1 -> 15 | DQ13: =DQ24+$DR$4-1 -> 17 | DR13: =SUM(DI13:DQ13) -> 141
A14: 10 | B14: Donaubowler Regensburg 1 | C14: 8 | D14: 3 | E14: 7 | F14: 4 | G14: 1 | H14: 9 | I14: 2 | J14: 5 | K14: 6 | L14: =SUM(C14:K14) -> 45 | M14: =M25+$V$4-1 -> 6 | N14: =N25+$V$4-1 -> 3 | O14: =O25+$V$4-1 -> 12 | P14: =P25+$V$4-1 -> 9 | Q14: =Q25+$V$4-1 -> 4 | R14: =R25+$V$4-1 -> 10 | S14: =S25+$V$4-1 -> 8 | T14: =T25+$V$4-1 -> 5 | U14: =U25+$V$4-1 -> 11 | V14: =SUM(M14:U14) -> 68 | W14: 6 | X14: 5 | Y14: 2 | Z14: 9 | AA14: 1 | AB14: 4 | AC14: 7 | AD14: 3 | AE14: 8 | AF14: =SUM(W14:AE14) -> 45 | AG14: =AG25+$AP$4-1 -> 17 | AH14: =AH25+$AP$4-1 -> 19 | AI14: =AI25+$AP$4-1 -> 12 | AJ14: =AJ25+$AP$4-1 -> 20 | AK14: =AK25+$AP$4-1 -> 14 | AL14: =AL25+$AP$4-1 -> 21 | AM14: =AM25+$AP$4-1 -> 16 | AN14: =AN25+$AP$4-1 -> 15 | AO14: =AO25+$AP$4-1 -> 18 | AP14: =SUM(AG14:AO14) -> 152 | AQ14: 3 | AR14: 2 | AS14: 7 | AT14: 8 | AU14: 5 | AV14: 9 | AW14: 4 | AX14: 6 | AY14: 1 | AZ14: =SUM(AQ14:AY14) -> 45 | BA14: =BA25+$BJ$4-1 -> 18 | BB14: =BB25+$BJ$4-1 -> 16 | BC14: =BC25+$BJ$4-1 -> 19 | BD14: =BD25+$BJ$4-1 -> 13 | BE14: =BE25+$BJ$4-1 -> 11 | BF14: =BF25+$BJ$4-1 -> 14 | BG14: =BG25+$BJ$4-1 -> 15 | BH14: =BH25+$BJ$4-1 -> 12 | BI14: =BI25+$BJ$4-1 -> 17 | BJ14: =SUM(BA14:BI14) -> 135 | BK14: 1 | BL14: 6 | BM14: 4 | BN14: 9 | BO14: 5 | BP14: 8 | BQ14: 7 | BR14: 2 | BS14: 3 | BT14: =SUM(BK14:BS14) -> 45 | BU14: =BU25+$CD$4-1 -> 20 | BV14: =BV25+$CD$4-1 -> 13 | BW14: =BW25+$CD$4-1 -> 12 | BX14: =BX25+$CD$4-1 -> 17 | BY14: =BY25+$CD$4-1 -> 14 | BZ14: =BZ25+$CD$4-1 -> 18 | CA14: =CA25+$CD$4-1 -> 16 | CB14: =CB25+$CD$4-1 -> 11 | CC14: =CC25+$CD$4-1 -> 19 | CD14: =SUM(BU14:CC14) -> 140 | CE14: 9 | CF14: 5 | CG14: 1 | CH14: 2 | CI14: 7 | CJ14: 4 | CK14: 3 | CL14: 6 | CM14: 8 | CN14: =SUM(CE14:CM14) -> 45 | CO14: =CO25+$CX$4-1 -> 13 | CP14: =CP25+$CX$4-1 -> 12 | CQ14: =CQ25+$CX$4-1 -> 17 | CR14: =CR25+$CX$4-1 -> 14 | CS14: =CS25+$CX$4-1 -> 19 | CT14: =CT25+$CX$4-1 -> 15 | CU14: =CU25+$CX$4-1 -> 11 | CV14: =CV25+$CX$4-1 -> 18 | CW14: =CW25+$CX$4-1 -> 20 | CX14: =SUM(CO14:CW14) -> 139 | CY14: 8 | CZ14: 6 | DA14: 3 | DB14: 4 | DC14: 7 | DD14: 2 | DE14: 1 | DF14: 5 | DG14: 9 | DH14: =SUM(CY14:DG14) -> 45 | DI14: =DI25+$DR$4-1 -> 11 | DJ14: =DJ25+$DR$4-1 -> 15 | DK14: =DK25+$DR$4-1 -> 14 | DL14: =DL25+$DR$4-1 -> 20 | DM14: =DM25+$DR$4-1 -> 12 | DN14: =DN25+$DR$4-1 -> 17 | DO14: =DO25+$DR$4-1 -> 16 | DP14: =DP25+$DR$4-1 -> 13 | DQ14: =DQ25+$DR$4-1 -> 18 | DR14: =SUM(DI14:DQ14) -> 136
C15: =SUM(C5:C14) -> 55 | D15: =SUM(D5:D14) -> 55 | E15: =SUM(E5:E14) -> 55 | F15: =SUM(F5:F14) -> 55 | G15: =SUM(G5:G14) -> 55 | H15: =SUM(H5:H14) -> 55 | I15: =SUM(I5:I14) -> 55 | J15: =SUM(J5:J14) -> 55 | K15: =SUM(K5:K14) -> 55 | M15: =SUM(M5:M14) -> 75 | N15: =SUM(N5:N14) -> 75 | O15: =SUM(O5:O14) -> 75 | P15: =SUM(P5:P14) -> 75 | Q15: =SUM(Q5:Q14) -> 75 | R15: =SUM(R5:R14) -> 75 | S15: =SUM(S5:S14) -> 75 | T15: =SUM(T5:T14) -> 75 | U15: =SUM(U5:U14) -> 75 | W15: =SUM(W5:W14) -> 55 | X15: =SUM(X5:X14) -> 55 | Y15: =SUM(Y5:Y14) -> 55 | Z15: =SUM(Z5:Z14) -> 55 | AA15: =SUM(AA5:AA14) -> 55 | AB15: =SUM(AB5:AB14) -> 55 | AC15: =SUM(AC5:AC14) -> 55 | AD15: =SUM(AD5:AD14) -> 55 | AE15: =SUM(AE5:AE14) -> 55 | AG15: =SUM(AG5:AG14) -> 165 | AH15: =SUM(AH5:AH14) -> 165 | AI15: =SUM(AI5:AI14) -> 165 | AJ15: =SUM(AJ5:AJ14) -> 165 | AK15: =SUM(AK5:AK14) -> 165 | AL15: =SUM(AL5:AL14) -> 165 | AM15: =SUM(AM5:AM14) -> 165 | AN15: =SUM(AN5:AN14) -> 165 | AO15: =SUM(AO5:AO14) -> 165 | AQ15: =SUM(AQ5:AQ14) -> 55 | AR15: =SUM(AR5:AR14) -> 55 | AS15: =SUM(AS5:AS14) -> 55 | AT15: =SUM(AT5:AT14) -> 55 | AU15: =SUM(AU5:AU14) -> 55 | AV15: =SUM(AV5:AV14) -> 55 | AW15: =SUM(AW5:AW14) -> 55 | AX15: =SUM(AX5:AX14) -> 55 | AY15: =SUM(AY5:AY14) -> 55 | BA15: =SUM(BA5:BA14) -> 155 | BB15: =SUM(BB5:BB14) -> 155 | BC15: =SUM(BC5:BC14) -> 155 | BD15: =SUM(BD5:BD14) -> 155 | BE15: =SUM(BE5:BE14) -> 155 | BF15: =SUM(BF5:BF14) -> 155 | BG15: =SUM(BG5:BG14) -> 155 | BH15: =SUM(BH5:BH14) -> 155 | BI15: =SUM(BI5:BI14) -> 155 | BK15: =SUM(BK5:BK14) -> 55 | BL15: =SUM(BL5:BL14) -> 55 | BM15: =SUM(BM5:BM14) -> 55 | BN15: =SUM(BN5:BN14) -> 55 | BO15: =SUM(BO5:BO14) -> 55 | BP15: =SUM(BP5:BP14) -> 55 | BQ15: =SUM(BQ5:BQ14) -> 55 | BR15: =SUM(BR5:BR14) -> 55 | BS15: =SUM(BS5:BS14) -> 55 | BU15: =SUM(BU5:BU14) -> 155 | BV15: =SUM(BV5:BV14) -> 155 | BW15: =SUM(BW5:BW14) -> 155 | BX15: =SUM(BX5:BX14) -> 155 | BY15: =SUM(BY5:BY14) -> 155 | BZ15: =SUM(BZ5:BZ14) -> 155 | CA15: =SUM(CA5:CA14) -> 155 | CB15: =SUM(CB5:CB14) -> 155 | CC15: =SUM(CC5:CC14) -> 155 | CE15: =SUM(CE5:CE14) -> 55 | CF15: =SUM(CF5:CF14) -> 55 | CG15: =SUM(CG5:CG14) -> 55 | CH15: =SUM(CH5:CH14) -> 55 | CI15: =SUM(CI5:CI14) -> 55 | CJ15: =SUM(CJ5:CJ14) -> 55 | CK15: =SUM(CK5:CK14) -> 55 | CL15: =SUM(CL5:CL14) -> 55 | CM15: =SUM(CM5:CM14) -> 55 | CO15: =SUM(CO5:CO14) -> 155 | CP15: =SUM(CP5:CP14) -> 155 | CQ15: =SUM(CQ5:CQ14) -> 155 | CR15: =SUM(CR5:CR14) -> 155 | CS15: =SUM(CS5:CS14) -> 155 | CT15: =SUM(CT5:CT14) -> 155 | CU15: =SUM(CU5:CU14) -> 155 | CV15: =SUM(CV5:CV14) -> 155 | CW15: =SUM(CW5:CW14) -> 155 | CY15: =SUM(CY5:CY14) -> 55 | CZ15: =SUM(CZ5:CZ14) -> 55 | DA15: =SUM(DA5:DA14) -> 55 | DB15: =SUM(DB5:DB14) -> 55 | DC15: =SUM(DC5:DC14) -> 55 | DD15: =SUM(DD5:DD14) -> 55 | DE15: =SUM(DE5:DE14) -> 55 | DF15: =SUM(DF5:DF14) -> 55 | DG15: =SUM(DG5:DG14) -> 55 | DI15: =SUM(DI5:DI14) -> 155 | DJ15: =SUM(DJ5:DJ14) -> 155 | DK15: =SUM(DK5:DK14) -> 155 | DL15: =SUM(DL5:DL14) -> 155 | DM15: =SUM(DM5:DM14) -> 155 | DN15: =SUM(DN5:DN14) -> 155 | DO15: =SUM(DO5:DO14) -> 155 | DP15: =SUM(DP5:DP14) -> 155 | DQ15: =SUM(DQ5:DQ14) -> 155
A16: 1 | B16: =+B5 -> BC Comet Nürnberg | M16: 5 | N16: 4 | O16: 7 | P16: 9 | Q16: 1 | R16: 3 | S16: 10 | T16: 8 | U16: 2 | V16: =SUM(M16:U16) -> 49 | AG16: 3 | AH16: 9 | AI16: 5 | AJ16: 8 | AK16: 4 | AL16: 6 | AM16: 10 | AN16: 7 | AO16: 2 | AP16: =SUM(AG16:AO16) -> 54 | BA16: 2 | BB16: 9 | BC16: 5 | BD16: 1 | BE16: 4 | BF16: 7 | BG16: 10 | BH16: 6 | BI16: 8 | BJ16: =SUM(BA16:BI16) -> 52 | BU16: 9 | BV16: 1 | BW16: 5 | BX16: 10 | BY16: 7 | BZ16: 4 | CA16: 2 | CB16: 6 | CC16: 3 | CD16: =SUM(BU16:CC16) -> 47 | CO16: 9 | CP16: 6 | CQ16: 8 | CR16: 10 | CS16: 2 | CT16: 4 | CU16: 7 | CV16: 5 | CW16: 1 | CX16: =SUM(CO16:CW16) -> 52 | DI16: 4 | DJ16: 10 | DK16: 6 | DL16: 7 | DM16: 3 | DN16: 1 | DO16: 5 | DP16: 9 | DQ16: 2 | DR16: =SUM(DI16:DQ16) -> 47
A17: 2 | B17: =+B6 -> BK München 3 | M17: 1 | N17: 9 | O17: 6 | P17: 4 | Q17: 8 | R17: 2 | S17: 5 | T17: 7 | U17: 3 | V17: =SUM(M17:U17) -> 45 | AG17: 8 | AH17: 10 | AI17: 2 | AJ17: 3 | AK17: 9 | AL17: 7 | AM17: 1 | AN17: 6 | AO17: 4 | AP17: =SUM(AG17:AO17) -> 50 | BA17: 10 | BB17: 5 | BC17: 4 | BD17: 2 | BE17: 6 | BF17: 9 | BG17: 1 | BH17: 7 | BI17: 3 | BJ17: =SUM(BA17:BI17) -> 47 | BU17: 8 | BV17: 10 | BW17: 4 | BX17: 6 | BY17: 1 | BZ17: 3 | CA17: 7 | CB17: 2 | CC17: 5 | CD17: =SUM(BU17:CC17) -> 46 | CO17: 10 | CP17: 7 | CQ17: 2 | CR17: 3 | CS17: 5 | CT17: 8 | CU17: 4 | CV17: 1 | CW17: 6 | CX17: =SUM(CO17:CW17) -> 46 | DI17: 9 | DJ17: 4 | DK17: 7 | DL17: 5 | DM17: 10 | DN17: 8 | DO17: 3 | DP17: 6 | DQ17: 1 | DR17: =SUM(DI17:DQ17) -> 53
A18: 3 | B18: =+B7 -> SG DJK Rimpar 1 | M18: 6 | N18: 2 | O18: 4 | P18: 5 | Q18: 7 | R18: 10 | S18: 3 | T18: 1 | U18: 8 | V18: =SUM(M18:U18) -> 46 | AG18: 9 | AH18: 4 | AI18: 8 | AJ18: 5 | AK18: 10 | AL18: 2 | AM18: 7 | AN18: 3 | AO18: 1 | AP18: =SUM(AG18:AO18) -> 49 | BA18: 7 | BB18: 10 | BC18: 3 | BD18: 6 | BE18: 8 | BF18: 1 | BG18: 4 | BH18: 9 | BI18: 2 | BJ18: =SUM(BA18:BI18) -> 50 | BU18: 3 | BV18: 6 | BW18: 7 | BX18: 4 | BY18: 9 | BZ18: 1 | CA18: 8 | CB18: 5 | CC18: 10 | CD18: =SUM(BU18:CC18) -> 53 | CO18: 6 | CP18: 10 | CQ18: 1 | CR18: 5 | CS18: 7 | CT18: 3 | CU18: 2 | CV18: 9 | CW18: 4 | CX18: =SUM(CO18:CW18) -> 47 | DI18: 7 | DJ18: 2 | DK18: 3 | DL18: 8 | DM18: 6 | DN18: 10 | DO18: 4 | DP18: 1 | DQ18: 9 | DR18: =SUM(DI18:DQ18) -> 50
A19: 4 | B19: =+B8 -> SG Rottendorf 1 | M19: 7 | N19: 10 | O19: 1 | P19: 8 | Q19: 3 | R19: 5 | S19: 9 | T19: 2 | U19: 6 | V19: =SUM(M19:U19) -> 51 | AG19: 1 | AH19: 3 | AI19: 6 | AJ19: 2 | AK19: 8 | AL19: 9 | AM19: 4 | AN19: 5 | AO19: 10 | AP19: =SUM(AG19:AO19) -> 48 | BA19: 5 | BB19: 3 | BC19: 2 | BD19: 7 | BE19: 9 | BF19: 8 | BG19: 6 | BH19: 10 | BI19: 4 | BJ19: =SUM(BA19:BI19) -> 54 | BU19: 7 | BV19: 5 | BW19: 1 | BX19: 9 | BY19: 6 | BZ19: 10 | CA19: 3 | CB19: 8 | CC19: 2 | CD19: =SUM(BU19:CC19) -> 51 | CO19: 5 | CP19: 3 | CQ19: 9 | CR19: 7 | CS19: 1 | CT19: 6 | CU19: 10 | CV19: 2 | CW19: 8 | CX19: =SUM(CO19:CW19) -> 51 | DI19: 5 | DJ19: 3 | DK19: 1 | DL19: 9 | DM19: 4 | DN19: 6 | DO19: 2 | DP19: 8 | DQ19: 10 | DR19: =SUM(DI19:DQ19) -> 48
A20: 5 | B20: =+B9 -> BC EMAX Unterföhring 2 | M20: 9 | N20: 7 | O20: 3 | P20: 10 | Q20: 6 | R20: 1 | S20: 8 | T20: 4 | U20: 5 | V20: =SUM(M20:U20) -> 53 | AG20: 2 | AH20: 7 | AI20: 9 | AJ20: 4 | AK20: 1 | AL20: 5 | AM20: 8 | AN20: 10 | AO20: 6 | AP20: =SUM(AG20:AO20) -> 52 | BA20: 1 | BB20: 4 | BC20: 7 | BD20: 10 | BE20: 2 | BF20: 6 | BG20: 3 | BH20: 8 | BI20: 5 | BJ20: =SUM(BA20:BI20) -> 46 | BU20: 2 | BV20: 9 | BW20: 8 | BX20: 1 | BY20: 3 | BZ20: 5 | CA20: 10 | CB20: 7 | CC20: 4 | CD20: =SUM(BU20:CC20) -> 49 | CO20: 7 | CP20: 1 | CQ20: 10 | CR20: 6 | CS20: 4 | CT20: 9 | CU20: 8 | CV20: 3 | CW20: 5 | CX20: =SUM(CO20:CW20) -> 53 | DI20: 10 | DJ20: 8 | DK20: 5 | DL20: 2 | DM20: 7 | DN20: 9 | DO20: 1 | DP20: 4 | DQ20: 6 | DR20: =SUM(DI20:DQ20) -> 52
A21: 6 | B21: =+B10 -> Bajuwaren München 1 | M21: 2 | N21: 5 | O21: 8 | P21: 1 | Q21: 4 | R21: 9 | S21: 7 | T21: 6 | U21: 10 | V21: =SUM(M21:U21) -> 52 | AG21: 5 | AH21: 1 | AI21: 10 | AJ21: 6 | AK21: 7 | AL21: 4 | AM21: 9 | AN21: 2 | AO21: 3 | AP21: =SUM(AG21:AO21) -> 47 | BA21: 6 | BB21: 2 | BC21: 8 | BD21: 5 | BE21: 3 | BF21: 10 | BG21: 7 | BH21: 1 | BI21: 9 | BJ21: =SUM(BA21:BI21) -> 51 | BU21: 6 | BV21: 4 | BW21: 10 | BX21: 5 | BY21: 8 | BZ21: 2 | CA21: 9 | CB21: 3 | CC21: 1 | CD21: =SUM(BU21:CC21) -> 48 | CO21: 8 | CP21: 5 | CQ21: 4 | CR21: 2 | CS21: 6 | CT21: 1 | CU21: 9 | CV21: 7 | CW21: 3 | CX21: =SUM(CO21:CW21) -> 45 | DI21: 8 | DJ21: 6 | DK21: 2 | DL21: 4 | DM21: 9 | DN21: 3 | DO21: 7 | DP21: 10 | DQ21: 5 | DR21: =SUM(DI21:DQ21) -> 54
A22: 7 | B22: =+B11 -> Bowlinghaus Bamberg 1 | M22: 8 | N22: 6 | O22: 9 | P22: 3 | Q22: 5 | R22: 4 | S22: 2 | T22: 10 | U22: 7 | V22: =SUM(M22:U22) -> 54 | AG22: 10 | AH22: 5 | AI22: 3 | AJ22: 7 | AK22: 2 | AL22: 8 | AM22: 6 | AN22: 1 | AO22: 9 | AP22: =SUM(AG22:AO22) -> 51 | BA22: 3 | BB22: 1 | BC22: 10 | BD22: 8 | BE22: 5 | BF22: 2 | BG22: 9 | BH22: 4 | BI22: 6 | BJ22: =SUM(BA22:BI22) -> 48 | BU22: 1 | BV22: 7 | BW22: 6 | BX22: 3 | BY22: 2 | BZ22: 9 | CA22: 5 | CB22: 4 | CC22: 8 | CD22: =SUM(BU22:CC22) -> 45 | CO22: 1 | CP22: 9 | CQ22: 3 | CR22: 8 | CS22: 10 | CT22: 7 | CU22: 6 | CV22: 4 | CW22: 2 | CX22: =SUM(CO22:CW22) -> 50 | DI22: 3 | DJ22: 7 | DK22: 9 | DL22: 6 | DM22: 1 | DN22: 5 | DO22: 8 | DP22: 2 | DQ22: 4 | DR22: =SUM(DI22:DQ22) -> 45
A23: 8 | B23: =+B12 -> Schanzer Ingolstadt 1 | M23: 3 | N23: 8 | O23: 5 | P23: 2 | Q23: 10 | R23: 6 | S23: 4 | T23: 9 | U23: 1 | V23: =SUM(M23:U23) -> 48 | AG23: 4 | AH23: 6 | AI23: 7 | AJ23: 1 | AK23: 5 | AL23: 3 | AM23: 2 | AN23: 9 | AO23: 8 | AP23: =SUM(AG23:AO23) -> 45 | BA23: 9 | BB23: 7 | BC23: 6 | BD23: 4 | BE23: 10 | BF23: 5 | BG23: 8 | BH23: 3 | BI23: 1 | BJ23: =SUM(BA23:BI23) -> 53 | BU23: 4 | BV23: 8 | BW23: 9 | BX23: 2 | BY23: 5 | BZ23: 7 | CA23: 1 | CB23: 10 | CC23: 6 | CD23: =SUM(BU23:CC23) -> 52 | CO23: 2 | CP23: 4 | CQ23: 5 | CR23: 1 | CS23: 8 | CT23: 10 | CU23: 3 | CV23: 6 | CW23: 9 | CX23: =SUM(CO23:CW23) -> 48 | DI23: 2 | DJ23: 9 | DK23: 8 | DL23: 1 | DM23: 5 | DN23: 4 | DO23: 10 | DP23: 7 | DQ23: 3 | DR23: =SUM(DI23:DQ23) -> 49
A24: 9 | B24: =+B13 -> Werdenfels 1 | M24: 10 | N24: 3 | O24: 2 | P24: 6 | Q24: 9 | R24: 7 | S24: 1 | T24: 5 | U24: 4 | V24: =SUM(M24:U24) -> 47 | AG24: 7 | AH24: 2 | AI24: 4 | AJ24: 10 | AK24: 6 | AL24: 1 | AM24: 3 | AN24: 8 | AO24: 5 | AP24: =SUM(AG24:AO24) -> 46 | BA24: 4 | BB24: 8 | BC24: 1 | BD24: 9 | BE24: 7 | BF24: 3 | BG24: 2 | BH24: 5 | BI24: 10 | BJ24: =SUM(BA24:BI24) -> 49 | BU24: 5 | BV24: 2 | BW24: 3 | BX24: 8 | BY24: 10 | BZ24: 6 | CA24: 4 | CB24: 9 | CC24: 7 | CD24: =SUM(BU24:CC24) -> 54 | CO24: 4 | CP24: 8 | CQ24: 6 | CR24: 9 | CS24: 3 | CT24: 2 | CU24: 5 | CV24: 10 | CW24: 7 | CX24: =SUM(CO24:CW24) -> 54 | DI24: 6 | DJ24: 1 | DK24: 10 | DL24: 3 | DM24: 8 | DN24: 2 | DO24: 9 | DP24: 5 | DQ24: 7 | DR24: =SUM(DI24:DQ24) -> 51
A25: 10 | B25: =+B14 -> Donaubowler Regensburg 1 | M25: 4 | N25: 1 | O25: 10 | P25: 7 | Q25: 2 | R25: 8 | S25: 6 | T25: 3 | U25: 9 | V25: =SUM(M25:U25) -> 50 | AG25: 6 | AH25: 8 | AI25: 1 | AJ25: 9 | AK25: 3 | AL25: 10 | AM25: 5 | AN25: 4 | AO25: 7 | AP25: =SUM(AG25:AO25) -> 53 | BA25: 8 | BB25: 6 | BC25: 9 | BD25: 3 | BE25: 1 | BF25: 4 | BG25: 5 | BH25: 2 | BI25: 7 | BJ25: =SUM(BA25:BI25) -> 45 | BU25: 10 | BV25: 3 | BW25: 2 | BX25: 7 | BY25: 4 | BZ25: 8 | CA25: 6 | CB25: 1 | CC25: 9 | CD25: =SUM(BU25:CC25) -> 50 | CO25: 3 | CP25: 2 | CQ25: 7 | CR25: 4 | CS25: 9 | CT25: 5 | CU25: 1 | CV25: 8 | CW25: 10 | CX25: =SUM(CO25:CW25) -> 49 | DI25: 1 | DJ25: 5 | DK25: 4 | DL25: 10 | DM25: 2 | DN25: 7 | DO25: 6 | DP25: 3 | DQ25: 8 | DR25: =SUM(DI25:DQ25) -> 46
M26: =SUM(M16:M25) -> 55 | N26: =SUM(N16:N25) -> 55 | O26: =SUM(O16:O25) -> 55 | P26: =SUM(P16:P25) -> 55 | Q26: =SUM(Q16:Q25) -> 55 | R26: =SUM(R16:R25) -> 55 | S26: =SUM(S16:S25) -> 55 | T26: =SUM(T16:T25) -> 55 | U26: =SUM(U16:U25) -> 55 | V26: =SUM(M26:U26) -> 495 | AG26: =SUM(AG16:AG25) -> 55 | AH26: =SUM(AH16:AH25) -> 55 | AI26: =SUM(AI16:AI25) -> 55 | AJ26: =SUM(AJ16:AJ25) -> 55 | AK26: =SUM(AK16:AK25) -> 55 | AL26: =SUM(AL16:AL25) -> 55 | AM26: =SUM(AM16:AM25) -> 55 | AN26: =SUM(AN16:AN25) -> 55 | AO26: =SUM(AO16:AO25) -> 55 | AP26: =SUM(AG26:AO26) -> 495 | BA26: =SUM(BA16:BA25) -> 55 | BB26: =SUM(BB16:BB25) -> 55 | BC26: =SUM(BC16:BC25) -> 55 | BD26: =SUM(BD16:BD25) -> 55 | BE26: =SUM(BE16:BE25) -> 55 | BF26: =SUM(BF16:BF25) -> 55 | BG26: =SUM(BG16:BG25) -> 55 | BH26: =SUM(BH16:BH25) -> 55 | BI26: =SUM(BI16:BI25) -> 55 | BJ26: =SUM(BA26:BI26) -> 495 | BU26: =SUM(BU16:BU25) -> 55 | BV26: =SUM(BV16:BV25) -> 55 | BW26: =SUM(BW16:BW25) -> 55 | BX26: =SUM(BX16:BX25) -> 55 | BY26: =SUM(BY16:BY25) -> 55 | BZ26: =SUM(BZ16:BZ25) -> 55 | CA26: =SUM(CA16:CA25) -> 55 | CB26: =SUM(CB16:CB25) -> 55 | CC26: =SUM(CC16:CC25) -> 55 | CD26: =SUM(BU26:CC26) -> 495 | CO26: =SUM(CO16:CO25) -> 55 | CP26: =SUM(CP16:CP25) -> 55 | CQ26: =SUM(CQ16:CQ25) -> 55 | CR26: =SUM(CR16:CR25) -> 55 | CS26: =SUM(CS16:CS25) -> 55 | CT26: =SUM(CT16:CT25) -> 55 | CU26: =SUM(CU16:CU25) -> 55 | CV26: =SUM(CV16:CV25) -> 55 | CW26: =SUM(CW16:CW25) -> 55 | CX26: =SUM(CO26:CW26) -> 495 | DI26: =SUM(DI16:DI25) -> 55 | DJ26: =SUM(DJ16:DJ25) -> 55 | DK26: =SUM(DK16:DK25) -> 55 | DL26: =SUM(DL16:DL25) -> 55 | DM26: =SUM(DM16:DM25) -> 55 | DN26: =SUM(DN16:DN25) -> 55 | DO26: =SUM(DO16:DO25) -> 55 | DP26: =SUM(DP16:DP25) -> 55 | DQ26: =SUM(DQ16:DQ25) -> 55 | DR26: =SUM(DI26:DQ26) -> 495

Sheet Member
A1: EDV-Nr. | B1: Passnr. | C1: Nachname | D1: Vorname | E1: Zus. | F1: Ges. | G1: AK | H1: RL | I1: Club | J1: Verein | K1: Kurz | L1: Column12 | M1: Column13 | N1: Column14 | O1: Column15 | P1: Column16 | Q1: Column17
A2: 38175 | B2: 131530 | C2: Bäßler | D2: Lars | F2: m | G2: Männer | H2: D | I2: BC Friedrichshafen | J2: 1. BBV Friedrichshafen e.V. | K2: FRI
A3: 3175 | B3: 162972 | C3: Hug | D3: Jürgen | F3: m | G3: Senioren A | H3: D | I3: BC Friedrichshafen | J3: 1. BBV Friedrichshafen e.V. | K3: FRI
A4: 7306 | B4: 115595 | C4: König | D4: Gabi | F4: w | G4: Seniorinnen B | H4: D | I4: BC Friedrichshafen | J4: 1. BBV Friedrichshafen e.V. | K4: FRI
A5: 25487 | B5: 60040 | C5: Morgen | D5: Markus | F5: m | G5: Männer | H5: D | I5: BC Friedrichshafen | J5: 1. BBV Friedrichshafen e.V. | K5: FRI
A6: 7291 | B6: 115597 | C6: Seiler | D6: Franz | F6: m | G6: Senioren C | H6: E | I6: BC Friedrichshafen | J6: 1. BBV Friedrichshafen e.V. | K6: FRI
A7: 25445 | B7: 125151 | C7: Seiler | D7: Ursula | F7: w | G7: Seniorinnen C | H7: E | I7: BC Friedrichshafen | J7: 1. BBV Friedrichshafen e.V. | K7: FRI
A8: 7295 | B8: 115593 | C8: Unternährer | D8: Peter | F8: m | G8: Senioren C | H8: D | I8: BC Friedrichshafen | J8: 1. BBV Friedrichshafen e.V. | K8: FRI
A9: 29170 | B9: 162959 | C9: Vogel | D9: Jens | F9: m | G9: Senioren B | H9: E | I9: BC Friedrichshafen | J9: 1. BBV Friedrichshafen e.V. | K9: FRI
A10: 38761 | B10: 155286 | C10: Gastinger | D10: Sandro | F10: m | G10: Männer | I10: Absolut Sports.com | J10: 1. BC Bad Tölz 78 e.V. | K10: TÖL
A11: 38001 | B11: 117987 | C11: Hanauer | D11: Florian | F11: m | G11: Männer | H11: A | I11: Absolut Sports.com | J11: 1. BC Bad Tölz 78 e.V. | K11: TÖL
A12: 16336 | B12: 116725 | C12: Hannemann | D12: Roland | F12: m | G12: Senioren A | H12: B | I12: Absolut Sports.com | J12: 1. BC Bad Tölz 78 e.V. | K12: TÖL
A13: 38954 | B13: 164079 | C13: Jehle | D13: Dennis | F13: m | G13: Männer | I13: Absolut Sports.com | J13: 1. BC Bad Tölz 78 e.V. | K13: TÖL
A14: 38845 | B14: 159631 | C14: Kugler | D14: Laurin | F14: m | G14: Jugend A m | H14: C | I14: Absolut Sports.com | J14: 1. BC Bad Tölz 78 e.V. | K14: TÖL
A15: 38843 | B15: 159629 | C15: Lintner | D15: Lena | F15: w | G15: Jugend B w | H15: F | I15: Absolut Sports.com | J15: 1. BC Bad Tölz 78 e.V. | K15: TÖL
A16: 25691 | B16: 162009 | C16: Mathe | D16: Thomas | F16: m | G16: Senioren A | H16: C | I16: Absolut Sports.com | J16: 1. BC Bad Tölz 78 e.V. | K16: TÖL
A17: 38844 | B17: 159630 | C17: Mathe | D17: Maximilian | F17: m | G17: Junioren | H17: D | I17: Absolut Sports.com | J17: 1. BC Bad Tölz 78 e.V. | K17: TÖL
A18: 38902 | B18: 162965 | C18: Mattes | D18: Marc | F18: m | G18: Männer | H18: D | I18: Absolut Sports.com | J18: 1. BC Bad Tölz 78 e.V. | K18: TÖL
A19: 38940 | B19: 164062 | C19: Mengel | D19: Marina | F19: w | G19: Jugend B w | I19: Absolut Sports.com | J19: 1. BC Bad Tölz 78 e.V. | K19: TÖL
A20: 28367 | B20: 24962 | C20: Müller | D20: Marcel | F20: m | G20: Männer | H20: A | I20: Absolut Sports.com | J20: 1. BC Bad Tölz 78 e.V. | K20: TÖL
A21: 25005 | B21: 29473 | C21: Mutz | D21: Anton | F21: m | G21: Senioren A | H21: B | I21: Absolut Sports.com | J21: 1. BC Bad Tölz 78 e.V. | K21: TÖL
A22: 38659 | B22: 148804 | C22: Nahodyl | D22: Jakob | F22: m | G22: Jugend A m | H22: B | I22: Absolut Sports.com | J22: 1. BC Bad Tölz 78 e.V. | K22: TÖL
A23: 38660 | B23: 148805 | C23: Nahodyl | D23: Valentin | F23: m | G23: Jugend A m | H23: B | I23: Absolut Sports.com | J23: 1. BC Bad Tölz 78 e.V. | K23: TÖL
A24: 38893 | B24: 162049 | C24: Rothemund | D24: Louis | F24: m | G24: Jugend C m | H24: F | I24: Absolut Sports.com | J24: 1. BC Bad Tölz 78 e.V. | K24: TÖL
A25: 7646 | B25: 116734 | C25: Schrempf | D25: Christian | F25: m | G25: Senioren A | H25: B | I25: Absolut Sports.com | J25: 1. BC Bad Tölz 78 e.V. | K25: TÖL
A26: 25690 | B26: 87201 | C26: Stangl | D26: Florian | F26: m | G26: Männer | H26: B | I26: Absolut Sports.com | J26: 1. BC Bad Tölz 78 e.V. | K26: TÖL
A27: 38149 | B27: 129876 | C27: Stockmann | D27: Uwe | F27: m | G27: Senioren B | I27: Absolut Sports.com | J27: 1. BC Bad Tölz 78 e.V. | K27: TÖL
A28: 38772 | B28: 158003 | C28: Sturm | D28: Sebastian | F28: m | G28: Jugend A m | H28: F | I28: Absolut Sports.com | J28: 1. BC Bad Tölz 78 e.V. | K28: TÖL
A29: 38530 | B29: 145415 | C29: Thurner | D29: Patrick | F29: m | G29: Männer | H29: A | I29: Absolut Sports.com | J29: 1. BC Bad Tölz 78 e.V. | K29: TÖL
A30: 38729 | B30: 153900 | C30: Waldinger | D30: Maximilian | F30: m | G30: Männer | I30: Absolut Sports.com | J30: 1. BC Bad Tölz 78 e.V. | K30: TÖL
A31: 38958 | B31: 164083 | C31: Weber | D31: Harald | F31: m | G31: Senioren A | I31: Absolut Sports.com | J31: 1. BC Bad Tölz 78 e.V. | K31: TÖL
A32: 25829 | B32: 107446 | C32: Zentara | D32: Helmut | F32: m | G32: Senioren A | H32: D | I32: Absolut Sports.com | J32: 1. BC Bad Tölz 78 e.V. | K32: TÖL
A33: 38352 | B33: 136757 | C33: Bückreiß | D33: Alexander | F33: m | G33: Senioren A | I33: Bowlingclub Coburg | J33: 1. BC Coburg e.V. | K33: COB
A34: 38539 | B34: 145502 | C34: Fischer | D34: Stephanie | F34: w | G34: Frauen | I34: Bowlingclub Coburg | J34: 1. BC Coburg e.V. | K34: COB
A35: 38540 | B35: 145503 | C35: Fischer | D35: Tobias | F35: m | G35: Männer | I35: Bowlingclub Coburg | J35: 1. BC Coburg e.V. | K35: COB
A36: 25359 | B36: 54392 | C36: Görbert | D36: René | F36: m | G36: Männer | I36: Bowlingclub Coburg | J36: 1. BC Coburg e.V. | K36: COB
A37: 25965 | B37: 111296 | C37: Keller | D37: Anja | F37: w | G37: Seniorinnen B | H37: E | I37: Bowlingclub Coburg | J37: 1. BC Coburg e.V. | K37: COB
A38: 38425 | B38: 140372 | C38: Lachmann | D38: Thomas | F38: m | G38: Senioren B | H38: F | I38: Bowlingclub Coburg | J38: 1. BC Coburg e.V. | K38: COB
A39: 38369 | B39: 136841 | C39: Noack | D39: Peter | F39: m | G39: Senioren B | I39: Bowlingclub Coburg | J39: 1. BC Coburg e.V. | K39: COB
A40: 16165 | B40: 115723 | C40: Schelhorn | D40: Heidemarie | F40: w | G40: Seniorinnen C | I40: Bowlingclub Coburg | J40: 1. BC Coburg e.V. | K40: COB
...

Sheet Starter
A1: 7102 | B1: =_xlfn.CONCAT(VLOOKUP(A1,Member!A:I,3,0)," ",VLOOKUP(A1,Member!A:I,4,0)) -> Schick Andreas | C1: =_xlfn.CONCAT(VLOOKUP(A1,Member!A:I,9,0)) -> Comet
A2: 16243 | B2: =_xlfn.CONCAT(VLOOKUP(A2,Member!A:I,3,0)," ",VLOOKUP(A2,Member!A:I,4,0)) -> Glatzer Daniel | C2: =_xlfn.CONCAT(VLOOKUP(A2,Member!A:I,9,0)) -> Comet
A3: 7724 | B3: =_xlfn.CONCAT(VLOOKUP(A3,Member!A:I,3,0)," ",VLOOKUP(A3,Member!A:I,4,0)) -> Schlick Christian | C3: =_xlfn.CONCAT(VLOOKUP(A3,Member!A:I,9,0)) -> Comet
A4: 16245 | B4: =_xlfn.CONCAT(VLOOKUP(A4,Member!A:I,3,0)," ",VLOOKUP(A4,Member!A:I,4,0)) -> Fischbach Max | C4: =_xlfn.CONCAT(VLOOKUP(A4,Member!A:I,9,0)) -> Comet
A5: 7734 | B5: =_xlfn.CONCAT(VLOOKUP(A5,Member!A:I,3,0)," ",VLOOKUP(A5,Member!A:I,4,0)) -> Schwarz Jan | C5: =_xlfn.CONCAT(VLOOKUP(A5,Member!A:I,9,0)) -> Comet
A6: 7725 | B6: =_xlfn.CONCAT(VLOOKUP(A6,Member!A:I,3,0)," ",VLOOKUP(A6,Member!A:I,4,0)) -> Schlundt Michael | C6: =_xlfn.CONCAT(VLOOKUP(A6,Member!A:I,9,0)) -> Comet
A7: 16896 | B7: =_xlfn.CONCAT(VLOOKUP(A7,Member!A:I,3,0)," ",VLOOKUP(A7,Member!A:I,4,0)) -> Mittelmaier Andreas | C7: =_xlfn.CONCAT(VLOOKUP(A7,Member!A:I,9,0)) -> Comet
A8: 25315 | B8: =_xlfn.CONCAT(VLOOKUP(A8,Member!A:I,3,0)," ",VLOOKUP(A8,Member!A:I,4,0)) -> Elze Ullrich | C8: =_xlfn.CONCAT(VLOOKUP(A8,Member!A:I,9,0)) -> BC Donau - Bowler
A9: 7830 | B9: =_xlfn.CONCAT(VLOOKUP(A9,Member!A:I,3,0)," ",VLOOKUP(A9,Member!A:I,4,0)) -> Hartfeil Volkmar | C9: =_xlfn.CONCAT(VLOOKUP(A9,Member!A:I,9,0)) -> BC Donau - Bowler
A10: 25271 | B10: =_xlfn.CONCAT(VLOOKUP(A10,Member!A:I,3,0)," ",VLOOKUP(A10,Member!A:I,4,0)) -> Hürdler Marco | C10: =_xlfn.CONCAT(VLOOKUP(A10,Member!A:I,9,0)) -> BC Donau - Bowler
A11: 25592 | B11: =_xlfn.CONCAT(VLOOKUP(A11,Member!A:I,3,0)," ",VLOOKUP(A11,Member!A:I,4,0)) -> Schießl Roland | C11: =_xlfn.CONCAT(VLOOKUP(A11,Member!A:I,9,0)) -> BC Donau - Bowler
A12: 10622 | B12: =_xlfn.CONCAT(VLOOKUP(A12,Member!A:I,3,0)," ",VLOOKUP(A12,Member!A:I,4,0)) -> Kreß Michael | C12: =_xlfn.CONCAT(VLOOKUP(A12,Member!A:I,9,0)) -> DJK Rimpar
... A25: 7597 | B25: =_xlfn.CONCAT(VLOOKUP(A25,Member!A:I,3,0)," ",VLOOKUP(A25,Member!A:I,4,0)) -> Laub Harald | C25: =_xlfn.CONCAT(VLOOKUP(A25,Member!A:I,9,0)) -> BK München
A26: 7886 | B26: Baszler Patrik | C26: BK München
A27: 7885 | B27: =_xlfn.CONCAT(VLOOKUP(A27,Member!A:I,3,0)," ",VLOOKUP(A27,Member!A:I,4,0)) -> Hinterwimmer Sebastian | C27: =_xlfn.CONCAT(VLOOKUP(A27,Member!A:I,9,0)) -> BK München
A28: 25788 | B28: =_xlfn.CONCAT(VLOOKUP(A28,Member!A:I,3,0)," ",VLOOKUP(A28,Member!A:I,4,0)) -> Auer Markus | C28: =_xlfn.CONCAT(VLOOKUP(A28,Member!A:I,9,0)) -> BC Werdenfels
A29: 25649 | B29: =_xlfn.CONCAT(VLOOKUP(A29,Member!A:I,3,0)," ",VLOOKUP(A29,Member!A:I,4,0)) -> Gärtner Bruno | C29: =_xlfn.CONCAT(VLOOKUP(A29,Member!A:I,9,0)) -> BC Werdenfels
A30: 25166 | B30: =_xlfn.CONCAT(VLOOKUP(A30,Member!A:I,3,0)," ",VLOOKUP(A30,Member!A:I,4,0)) -> Musiol Jan | C30: =_xlfn.CONCAT(VLOOKUP(A30,Member!A:I,9,0)) -> BC Werdenfels
A31: 25822 | B31: =_xlfn.CONCAT(VLOOKUP(A31,Member!A:I,3,0)," ",VLOOKUP(A31,Member!A:I,4,0)) -> Kammermeier Maximilian | C31: =_xlfn.CONCAT(VLOOKUP(A31,Member!A:I,9,0)) -> BC Werdenfels
A32: 25554 | B32: =_xlfn.CONCAT(VLOOKUP(A32,Member!A:I,3,0)," ",VLOOKUP(A32,Member!A:I,4,0)) -> Blasits Ernst | C32: =_xlfn.CONCAT(VLOOKUP(A32,Member!A:I,9,0)) -> BC EMAX
A33: 7602 | B33: =_xlfn.CONCAT(VLOOKUP(A33,Member!A:I,3,0)," ",VLOOKUP(A33,Member!A:I,4,0)) -> Probst Marco | C33: =_xlfn.CONCAT(VLOOKUP(A33,Member!A:I,9,0)) -> BC EMAX
A34: 27134 | B34: =_xlfn.CONCAT(VLOOKUP(A34,Member!A:I,3,0)," ",VLOOKUP(A34,Member!A:I,4,0)) -> Lohse Sebastian | C34: =_xlfn.CONCAT(VLOOKUP(A34,Member!A:I,9,0)) -> BC EMAX
A35: 7883 | B35: =_xlfn.CONCAT(VLOOKUP(A35,Member!A:I,3,0)," ",VLOOKUP(A35,Member!A:I,4,0)) -> Hofbauer Karlheinz | C35: =_xlfn.CONCAT(VLOOKUP(A35,Member!A:I,9,0)) -> BC EMAX
A36: 7408 | B36: =_xlfn.CONCAT(VLOOKUP(A36,Member!A:I,3,0)," ",VLOOKUP(A36,Member!A:I,4,0)) -> Glasl Hans-Jürgen | C36: =_xlfn.CONCAT(VLOOKUP(A36,Member!A:I,9,0)) -> BC Bajuwaren
A37: 16762 | B37: =_xlfn.CONCAT(VLOOKUP(A37,Member!A:I,3,0)," ",VLOOKUP(A37,Member!A:I,4,0)) -> Glasl sen. Hans-Jürgen | C37: =_xlfn.CONCAT(VLOOKUP(A37,Member!A:I,9,0)) -> BC Bajuwaren
A38: 7600 | B38: =_xlfn.CONCAT(VLOOKUP(A38,Member!A:I,3,0)," ",VLOOKUP(A38,Member!A:I,4,0)) -> Lüthje Dennis | C38: =_xlfn.CONCAT(VLOOKUP(A38,Member!A:I,9,0)) -> BC Bajuwaren
... A59: 7831 | B59: =_xlfn.CONCAT(VLOOKUP(A59,Member!A:I,3,0)," ",VLOOKUP(A59,Member!A:I,4,0)) -> Obermeier Kurt | C59: =_xlfn.CONCAT(VLOOKUP(A59,Member!A:I,9,0)) -> BC Donau - Bowler
B60: =_xlfn.CONCAT(VLOOKUP(A60,Member!A:I,3,0)," ",VLOOKUP(A60,Member!A:I,4,0)) -> #N/A | C60: =_xlfn.CONCAT(VLOOKUP(A60,Member!A:I,9,0)) -> #N/A
B61: =_xlfn.CONCAT(VLOOKUP(A61,Member!A:I,3,0)," ",VLOOKUP(A61,Member!A:I,4,0)) -> #N/A | C61: =_xlfn.CONCAT(VLOOKUP(A61,Member!A:I,9,0)) -> #N/A
B62: =_xlfn.CONCAT(VLOOKUP(A62,Member!A:I,3,0)," ",VLOOKUP(A62,Member!A:I,4,0)) -> #N/A | C62: =_xlfn.CONCAT(VLOOKUP(A62,Member!A:I,9,0)) -> #N/A
B63: =_xlfn.CONCAT(VLOOKUP(A63,Member!A:I,3,0)," ",VLOOKUP(A63,Member!A:I,4,0)) -> #N/A | C63: =_xlfn.CONCAT(VLOOKUP(A63,Member!A:I,9,0)) -> #N/A
B64: =_xlfn.CONCAT(VLOOKUP(A64,Member!A:I,3,0)," ",VLOOKUP(A64,Member!A:I,4,0)) -> #N/A | C64: =_xlfn.CONCAT(VLOOKUP(A64,Member!A:I,9,0)) -> #N/A
B65: =_xlfn.CONCAT(VLOOKUP(A65,Member!A:I,3,0)," ",VLOOKUP(A65,Member!A:I,4,0)) -> #N/A | C65: =_xlfn.CONCAT(VLOOKUP(A65,Member!A:I,9,0)) -> #N/A
B66: =_xlfn.CONCAT(VLOOKUP(A66,Member!A:I,3,0)," ",VLOOKUP(A66,Member!A:I,4,0)) -> #N/A | C66: =_xlfn.CONCAT(VLOOKUP(A66,Member!A:I,9,0)) -> #N/A
B67: =_xlfn.CONCAT(VLOOKUP(A67,Member!A:I,3,0)," ",VLOOKUP(A67,Member!A:I,4,0)) -> #N/A | C67: =_xlfn.CONCAT(VLOOKUP(A67,Member!A:I,9,0)) -> #N/A
B68: =_xlfn.CONCAT(VLOOKUP(A68,Member!A:I,3,0)," ",VLOOKUP(A68,Member!A:I,4,0)) -> #N/A | C68: =_xlfn.CONCAT(VLOOKUP(A68,Member!A:I,9,0)) -> #N/A
B69: =_xlfn.CONCAT(VLOOKUP(A69,Member!A:I,3,0)," ",VLOOKUP(A69,Member!A:I,4,0)) -> #N/A | C69: =_xlfn.CONCAT(VLOOKUP(A69,Member!A:I,9,0)) -> #N/A
B70: =_xlfn.CONCAT(VLOOKUP(A70,Member!A:I,3,0)," ",VLOOKUP(A70,Member!A:I,4,0)) -> #N/A | C70: =_xlfn.CONCAT(VLOOKUP(A70,Member!A:I,9,0)) -> #N/A
B71: =_xlfn.CONCAT(VLOOKUP(A71,Member!A:I,3,0)," ",VLOOKUP(A71,Member!A:I,4,0)) -> #N/A | C71: =_xlfn.CONCAT(VLOOKUP(A71,Member!A:I,9,0)) -> #N/A
... B99: =_xlfn.CONCAT(VLOOKUP(A99,Member!A:I,3,0)," ",VLOOKUP(A99,Member!A:I,4,0)) -> #N/A | C99: =_xlfn.CONCAT(VLOOKUP(A99,Member!A:I,9,0)) -> #N/A

Sheet Schiedsrichterinfos
A1: =Schlüssel!C1&" - Saison "&Spielorte!C18 -> Bayernliga Herren - Saison 2025/2026
A3: Ligasprecher:
A4: Stellvertreter:
A6: Ahndungen bis Spieltag | C6: 1 | K6: Legende
A7: EDV | B7: Name | C7: Team | D7: 1. ST | E7: 2. ST | F7: 3. ST | G7: 4. ST | H7: 5. ST | I7: 6. ST | J7: Bemerkungen | K7: V | L7: Verwarnung
K8: G | L8: Gelbe Karte
K9: R | L9: Rote Karte
K10: D | L10: Spielerdokumente nicht vollständig
K11: S | L11: Spieler ist gesperrt

Sheet SRBericht1
B2: Schiedsrichterbericht
G6: Spieltag | H6: =Schlüssel!S2 -> 1 | M6: Datum | N6: =Schlüssel!M1 -> 04.10./05.10. | O6: 0 | P6: 0 | Q6: 0
G8: Liga | H8: =Schlüssel!C1 -> Bayernliga Herren
G10: Anlage | H10: =Schlüssel!C2 -> Regensburg Super Bowl
G12: Name Schiedsrichter: | H12: Jürgen Winecki
G14: Verein: | H14: BV 68 Regensburg
G16: Rolle: | H16: X | I16: Schiedsrichter
I18: Spielender Schiedsrichter
I20: Auswerter
C24: Beurteilung der Anlage
C25: Hallenöffnung um | M25: 0.35416667 | N25: Uhr
C28: Ölbild ausgehängt | G28: X | I28: Ja | M28: Nein
C30: Bahnenölung i.O. | G30: X | I30: Ja | M30: Nein
C31: wenn nein, Grund
C34: Foullinien i.O.
C35: und eingeschaltet | I35: Ja | K35: X | M35: Nein
C36: wenn nein, Grund
C37: Defekt
C39: Bahnenpflege in
C40: der Mittagspause | I40: Ja | M40: Nein
C41: wenn nein, Grund
B44: Mittagspause von | I44: 0.51041667 | K44: bis | M44: 0.52083333 | N44: Uhr
C47: Bahnenstopps: | I47: Ja | K47: X | M47: Nein
C48: wenn ja, Anzahl
C49: Grund
C53: Pinverwerfungen: | G53: X | I53: 0 - 10 | M53: 11 - 20 | Q53: über 20
C54: evtl. Bahnnr.:
B56: Besondere Vorkommnisse:
C58: Bahn 3 Stopp Pins verdreht
C61: Spielkontrolle
C65: EDV | E65: Name | I65: Grund | O65: Mündliche Verwarnung | P65: Weiße Karte | Q65: Gelbe Karte | R65: Gelb+Rote Karte | S65: Rote Karte
D66: =IF(C66=0,"",_xlfn.CONCAT(VLOOKUP(C66,#REF!,3,FALSE)," ",VLOOKUP(C66,#REF!,4,FALSE)))
D67: =IF(C67=0,"",_xlfn.CONCAT(VLOOKUP(C67,#REF!,3,FALSE)," ",VLOOKUP(C67,#REF!,4,FALSE)))
D68: =IF(C68=0,"",_xlfn.CONCAT(VLOOKUP(C68,#REF!,3,FALSE)," ",VLOOKUP(C68,#REF!,4,FALSE)))
D69: =IF(C69=0,"",_xlfn.CONCAT(VLOOKUP(C69,#REF!,3,FALSE)," ",VLOOKUP(C69,#REF!,4,FALSE)))
D70: =IF(C70=0,"",_xlfn.CONCAT(VLOOKUP(C70,#REF!,3,FALSE)," ",VLOOKUP(C70,#REF!,4,FALSE)))
D71: =IF(C71=0,"",_xlfn.CONCAT(VLOOKUP(C71,#REF!,3,FALSE)," ",VLOOKUP(C71,#REF!,4,FALSE)))
D72: =IF(C72=0,"",_xlfn.CONCAT(VLOOKUP(C72,#REF!,3,FALSE)," ",VLOOKUP(C72,#REF!,4,FALSE)))
D73: =IF(C73=0,"",_xlfn.CONCAT(VLOOKUP(C73,#REF!,3,FALSE)," ",VLOOKUP(C73,#REF!,4,FALSE)))
D74: =IF(C74=0,"",_xlfn.CONCAT(VLOOKUP(C74,#REF!,3,FALSE)," ",VLOOKUP(C74,#REF!,4,FALSE)))
...

Sheet TabGes
A1: =Schlüssel!$C$1 -> Bayernliga Herren
A2: ="Saison "&Spielorte!C18&" - Spieltag "&Erfassung6!AD2&" - "&TEXT(Erfassung6!AD1,"T. MMMM JJJJ") -> Saison 2025/2026 - Spieltag - 0. Januar 1900
A3: Gesamttabelle
A5: Pl. | B5: Mannschaften | C5: Spieltag 1 | E5: Spieltag 2 | G5: Spieltag 3 | I5: Spieltag 4 | K5: Spieltag 5 | M5: Spieltag 6 | O5: Gesamt | Q5: Schnitt | U5: Mannschaften | V5: Spieltag 1 | X5: Spieltag 2 | Z5: Spieltag 3 | AB5: Spieltag 4 | AD5: Spieltag 5 | AF5: Spieltag 6 | AH5: Gesamt | AJ5: Schnitt | AK5: Pins + PKT | AL5: Rang
C6: Pins | D6: Pkt. | E6: Pins | F6: Pkt. | G6: Pins | H6: Pkt. | I6: Pins | J6: Pkt. | K6: Pins | L6: Pkt. | M6: Pins | N6: Pkt. | O6: Pins | P6: Pkt. | V6: Pins | W6: Pkt. | X6: Pins | Y6: Pkt. | Z6: Pins | AA6: Pkt. | AB6: Pins | AC6: Pkt. | AD6: Pins | AE6: Pkt. | AF6: Pins | AG6: Pkt. | AH6: Pins | AI6: Pkt.
A7: 1 | B7: =VLOOKUP(A7,AL:AM,2,0) -> BK München 3 | C7: =VLOOKUP(B7,U:AL,2,0) -> 6829 | D7: =VLOOKUP(B7,U:AL,3,0) -> 51 | E7: =VLOOKUP(B7,U:AL,4,0) -> 0 | F7: =VLOOKUP(B7,U:AL,5,0) -> 0 | G7: =VLOOKUP(B7,U:AL,6,0) -> 0 | H7: =VLOOKUP(B7,U:AL,7,0) -> 0 | I7: =VLOOKUP(B7,U:AL,8,0) -> 0 | J7: =VLOOKUP(B7,U:AL,9,0) -> 0 | K7: =VLOOKUP(B7,U:AL,10,0) -> 0 | L7: =VLOOKUP(B7,U:AL,11,0) -> 0 | M7: =VLOOKUP(B7,U:AL,12,0) -> 0 | N7: =VLOOKUP(B7,U:AL,13,0) -> 0 | O7: =SUM(C7+E7+G7+I7+K7+M7) -> 6829 | P7: =SUM(D7+F7+H7+J7+L7+N7) -> 51 | Q7: =VLOOKUP(B7,U:AL,16,0) -> 189.69444 | U7: =Schlüssel!B5 -> BC Comet Nürnberg | V7: =VLOOKUP($U7,Tabelle1!$B$4:$W$16,20,0) -> 6680 | W7: =VLOOKUP($U7,Tabelle1!$B$4:$W$16,21,0) -> 43 | X7: =VLOOKUP(U7,Tabelle2!$B$4:$W$16,20,0) -> 0 | Y7: =VLOOKUP(U7,Tabelle2!$B$4:$W$16,21,0) -> 0 | Z7: =VLOOKUP(U7,Tabelle3!$B$4:$W$16,20,0) -> 0 | AA7: =VLOOKUP(U7,Tabelle3!$B$4:$W$16,21,0) -> 0 | AB7: =VLOOKUP(U7,Tabelle4!$B$4:$W$16,20,0) -> 0 | AC7: =VLOOKUP(U7,Tabelle4!$B$4:$W$16,21,0) -> 0 | AD7: =VLOOKUP(U7,Tabelle4!$B$4:$W$16,20,0) -> 0 | AE7: =VLOOKUP(U7,Tabelle4!$B$4:$W$16,21,0) -> 0 | AF7: =VLOOKUP(U7,Tabelle4!$B$4:$W$16,20,0) -> 0 | AG7: =VLOOKUP(U7,Tabelle4!$B$4:$W$16,21,0) -> 0 | AH7: =SUM(V7+X7+Z7+AB7+AD7+AF7) -> 6680 | AI7: =SUM(W7+Y7+AA7+AC7+AE7+AG7) -> 43 | AJ7: =AH7/AX7 -> 185.55556 | AK7: =AI7+AH7*0.00000000001 -> 43 | AL7: =RANK(AK7,AK$7:AK$16) -> 2 | AM7: {=U7:U12} -> BC Comet Nürnberg | AQ7: =Erfassung1!BF20 -> 36 | AR7: =Erfassung2!BF20 -> 0 | AS7: =Erfassung3!BF20 -> 0 | AT7: =Erfassung4!BF20 -> 0 | AU7: =Erfassung5!BF20 -> 0 | AV7: =Erfassung6!BF20 -> 0 | AX7: =SUM(AQ7:AV7) -> 36
